Workbook

Sheet Raw data
A1: 시도별(1) | B1: 시도별(2) | C1: 2005 | D1: 2005 | E1: 2005 | F1: 2005 | G1: 2005 | H1: 2005 | I1: 2005 | J1: 2005 | K1: 2005 | L1: 2005 | M1: 2005 | N1: 2005 | O1: 2005 | P1: 2005 | Q1: 2005 | R1: 2005 | S1: 2005 | T1: 2006 | U1: 2006 | V1: 2006 | W1: 2006 | X1: 2006 | Y1: 2006 | Z1: 2006 | AA1: 2006 | AB1: 2006 | AC1: 2006 | AD1: 2006 | AE1: 2006 | AF1: 2006 | AG1: 2006 | AH1: 2006 | AI1: 2006 | AJ1: 2006 | AK1: 2007 | AL1: 2007 | AM1: 2007 | AN1: 2007 | AO1: 2007 | AP1: 2007 | AQ1: 2007 | AR1: 2007 | AS1: 2007 | AT1: 2007 | AU1: 2007 | AV1: 2007 | AW1: 2007 | AX1: 2007 | AY1: 2007 | AZ1: 2007 | BA1: 2007 | BB1: 2008 | BC1: 2008 | BD1: 2008 | BE1: 2008 | BF1: 2008 | BG1: 2008 | BH1: 2008 | BI1: 2008 | BJ1: 2008 | BK1: 2008 | BL1: 2008 | BM1: 2008 | BN1: 2008 | BO1: 2008 | BP1: 2008 | BQ1: 2008 | BR1: 2008 | BS1: 2009 | BT1: 2009 | BU1: 2009 | BV1: 2009 | BW1: 2009 | BX1: 2009 | BY1: 2009 | BZ1: 2009 | CA1: 2009 | CB1: 2009 | CC1: 2009 | CD1: 2009 | CE1: 2009 | CF1: 2009 | CG1: 2009 | CH1: 2009 | CI1: 2009 | CJ1: 2010 | CK1: 2010 | CL1: 2010 | CM1: 2010 | CN1: 2010 | CO1: 2010 | CP1: 2010 | CQ1: 2010 | CR1: 2010 | CS1: 2010 | CT1: 2010 | CU1: 2010 | CV1: 2010 | CW1: 2010 | CX1: 2010 | CY1: 2010 | CZ1: 2010 | DA1: 2011 | DB1: 2011 | DC1: 2011 | DD1: 2011 | DE1: 2011 | DF1: 2011 | DG1: 2011 | DH1: 2011 | DI1: 2011 | DJ1: 2011 | DK1: 2011 | DL1: 2011 | DM1: 2011 | DN1: 2011 | DO1: 2011 | DP1: 2011 | DQ1: 2011 | DR1: 2012 | DS1: 2012 | DT1: 2012 | DU1: 2012 | DV1: 2012 | DW1: 2012 | DX1: 2012 | DY1: 2012 | DZ1: 2012 | EA1: 2012 | EB1: 2012 | EC1: 2012 | ED1: 2012 | EE1: 2012 | EF1: 2012 | EG1: 2012 | EH1: 2012 | EI1: 2013 | EJ1: 2013 | EK1: 2013 | EL1: 2013 | EM1: 2013 | EN1: 2013 | EO1: 2013 | EP1: 2013 | EQ1: 2013 | ER1: 2013 | ES1: 2013 | ET1: 2013 | EU1: 2013 | EV1: 2013 | EW1: 2013 | EX1: 2013 | EY1: 2013 | EZ1: 2014 | FA1: 2014 | FB1: 2014 | FC1: 2014 | FD1: 2014 | FE1: 2014 | FF1: 2014 | FG1: 2014 | FH1: 2014 | FI1: 2014 | FJ1: 2014 | FK1: 2014 | FL1: 2014 | FM1: 2014 | FN1: 2014 | FO1: 2014 | FP1: 2014 | FQ1: 2015 | FR1: 2015 | FS1: 2015 | FT1: 2015 | FU1: 2015 | FV1: 2015 | FW1: 2015 | FX1: 2015 | FY1: 2015 | FZ1: 2015 | GA1: 2015 | GB1: 2015 | GC1: 2015 | GD1: 2015 | GE1: 2015 | GF1: 2015 | GG1: 2015 | GH1: 2016 | GI1: 2016 | GJ1: 2016 | GK1: 2016 | GL1: 2016 | GM1: 2016 | GN1: 2016 | GO1: 2016 | GP1: 2016 | GQ1: 2016 | GR1: 2016 | GS1: 2016 | GT1: 2016 | GU1: 2016 | GV1: 2016 | GW1: 2016 | GX1: 2016 | GY1: 2017 | GZ1: 2017 | HA1: 2017 | HB1: 2017 | HC1: 2017 | HD1: 2017 | HE1: 2017 | HF1: 2017 | HG1: 2017 | HH1: 2017 | HI1: 2017 | HJ1: 2017 | HK1: 2017 | HL1: 2017 | HM1: 2017 | HN1: 2017 | HO1: 2017 | HP1: 2018 | HQ1: 2018 | HR1: 2018 | HS1: 2018 | HT1: 2018 | HU1: 2018 | HV1: 2018 | HW1: 2018 | HX1: 2018 | HY1: 2018 | HZ1: 2018 | IA1: 2018 | IB1: 2018 | IC1: 2018 | ID1: 2018 | IE1: 2018 | IF1: 2018 | IG1: 2019 | IH1: 2019 | II1: 2019 | IJ1: 2019 | IK1: 2019 | IL1: 2019 | IM1: 2019 | IN1: 2019 | IO1: 2019 | IP1: 2019 | IQ1: 2019 | IR1: 2019 | IS1: 2019 | IT1: 2019 | IU1: 2019 | IV1: 2019 | IW1: 2019 | IX1: 2020 | IY1: 2020 | IZ1: 2020 | JA1: 2020 | JB1: 2020 | JC1: 2020 | JD1: 2020 | JE1: 2020 | JF1: 2020 | JG1: 2020 | JH1: 2020 | JI1: 2020 | JJ1: 2020 | JK1: 2020 | JL1: 2020 | JM1: 2020 | JN1: 2020 | JO1: 2021 | JP1: 2021 | JQ1: 2021 | JR1: 2021 | JS1: 2021 | JT1: 2021 | JU1: 2021 | JV1: 2021 | JW1: 2021 | JX1: 2021 | JY1: 2021 | JZ1: 2021 | KA1: 2021 | KB1: 2021 | KC1: 2021 | KD1: 2021 | KE1: 2021 | KF1: 2022 | KG1: 2022 | KH1: 2022 | KI1: 2022 | KJ1: 2022 | KK1: 2022 | KL1: 2022 | KM1: 2022 | KN1: 2022 | KO1: 2022 | KP1: 2022 | KQ1: 2022 | KR1: 2022 | KS1: 2022 | KT1: 2022 | KU1: 2022 | KV1: 2022 | KW1: 2023 | KX1: 2023 | KY1: 2023 | KZ1: 2023 | LA1: 2023 | LB1: 2023 | LC1: 2023 | LD1: 2023 | LE1: 2023 | LF1: 2023 | LG1: 2023 | LH1: 2023 | LI1: 2023 | LJ1: 2023 | LK1: 2023 | LL1: 2023 | LM1: 2023 | LN1: 2024 | LO1: 2024 | LP1: 2024 | LQ1: 2024 | LR1: 2024 | LS1: 2024 | LT1: 2024 | LU1: 2024 | LV1: 2024 | LW1: 2024 | LX1: 2024 | LY1: 2024 | LZ1: 2024 | MA1: 2024 | MB1: 2024 | MC1: 2024 | MD1: 2024 | ME1: 2025 | MF1: 2025 | MG1: 2025 | MH1: 2025 | MI1: 2025 | MJ1: 2025 | MK1: 2025 | ML1: 2025 | MM1: 2025 | MN1: 2025 | MO1: 2025 | MP1: 2025 | MQ1: 2025 | MR1: 2025 | MS1: 2025 | MT1: 2025 | MU1: 2025 | MV1: 2026 | MW1: 2026 | MX1: 2026 | MY1: 2026 | MZ1: 2026 | NA1: 2026 | NB1: 2026 | NC1: 2026 | ND1: 2026 | NE1: 2026 | NF1: 2026 | NG1: 2026 | NH1: 2026 | NI1: 2026 | NJ1: 2026 | NK1: 2026 | NL1: 2026
A2: 시도별(1) | B2: 시도별(2) | C2: 합계:면적 (ha) | D2: 합계:생산량 (톤) | E2: 고구마:면적 (ha) | F2: 고구마:10a당 생산량 (kg) | G2: 고구마:생산량 (톤) | H2: 감자:면적 (ha) | I2: 감자:10a당 생산량 (kg) | J2: 감자:생산량 (톤) | K2: 일반봄감자:면적 (ha) | L2: 일반봄감자:10a당 생산량 (kg) | M2: 일반봄감자:생산량 (톤) | N2: 고랭지감자:면적 (ha) | O2: 고랭지감자:10a당 생산량 (kg) | P2: 고랭지감자:생산량 (톤) | Q2: 가을감자:면적 (ha) | R2: 가을감자:10a당 생산량 (kg) | S2: 가을감자:생산량 (톤) | T2: 합계:면적 (ha) | U2: 합계:생산량 (톤) | V2: 고구마:면적 (ha) | W2: 고구마:10a당 생산량 (kg) | X2: 고구마:생산량 (톤) | Y2: 감자:면적 (ha) | Z2: 감자:10a당 생산량 (kg) | AA2: 감자:생산량 (톤) | AB2: 일반봄감자:면적 (ha) | AC2: 일반봄감자:10a당 생산량 (kg) | AD2: 일반봄감자:생산량 (톤) | AE2: 고랭지감자:면적 (ha) | AF2: 고랭지감자:10a당 생산량 (kg) | AG2: 고랭지감자:생산량 (톤) | AH2: 가을감자:면적 (ha) | AI2: 가을감자:10a당 생산량 (kg) | AJ2: 가을감자:생산량 (톤) | AK2: 합계:면적 (ha) | AL2: 합계:생산량 (톤) | AM2: 고구마:면적 (ha) | AN2: 고구마:10a당 생산량 (kg) | AO2: 고구마:생산량 (톤) | AP2: 감자:면적 (ha) | AQ2: 감자:10a당 생산량 (kg) | AR2: 감자:생산량 (톤) | AS2: 일반봄감자:면적 (ha) | AT2: 일반봄감자:10a당 생산량 (kg) | AU2: 일반봄감자:생산량 (톤) | AV2: 고랭지감자:면적 (ha) | AW2: 고랭지감자:10a당 생산량 (kg) | AX2: 고랭지감자:생산량 (톤) | AY2: 가을감자:면적 (ha) | AZ2: 가을감자:10a당 생산량 (kg) | BA2: 가을감자:생산량 (톤) | BB2: 합계:면적 (ha) | BC2: 합계:생산량 (톤) | BD2: 고구마:면적 (ha) | BE2: 고구마:10a당 생산량 (kg) | BF2: 고구마:생산량 (톤) | BG2: 감자:면적 (ha) | BH2: 감자:10a당 생산량 (kg) | BI2: 감자:생산량 (톤) | BJ2: 일반봄감자:면적 (ha) | BK2: 일반봄감자:10a당 생산량 (kg) | BL2: 일반봄감자:생산량 (톤) | BM2: 고랭지감자:면적 (ha) | BN2: 고랭지감자:10a당 생산량 (kg) | BO2: 고랭지감자:생산량 (톤) | BP2: 가을감자:면적 (ha) | BQ2: 가을감자:10a당 생산량 (kg) | BR2: 가을감자:생산량 (톤) | BS2: 합계:면적 (ha) | BT2: 합계:생산량 (톤) | BU2: 고구마:면적 (ha) | BV2: 고구마:10a당 생산량 (kg) | BW2: 고구마:생산량 (톤) | BX2: 감자:면적 (ha) | BY2: 감자:10a당 생산량 (kg) | BZ2: 감자:생산량 (톤) | CA2: 일반봄감자:면적 (ha) | CB2: 일반봄감자:10a당 생산량 (kg) | CC2: 일반봄감자:생산량 (톤) | CD2: 고랭지감자:면적 (ha) | CE2: 고랭지감자:10a당 생산량 (kg) | CF2: 고랭지감자:생산량 (톤) | CG2: 가을감자:면적 (ha) | CH2: 가을감자:10a당 생산량 (kg) | CI2: 가을감자:생산량 (톤) | CJ2: 합계:면적 (ha) | CK2: 합계:생산량 (톤) | CL2: 고구마:면적 (ha) | CM2: 고구마:10a당 생산량 (kg) | CN2: 고구마:생산량 (톤) | CO2: 감자:면적 (ha) | CP2: 감자:10a당 생산량 (kg) | CQ2: 감자:생산량 (톤) | CR2: 일반봄감자:면적 (ha) | CS2: 일반봄감자:10a당 생산량 (kg) | CT2: 일반봄감자:생산량 (톤) | CU2: 고랭지감자:면적 (ha) | CV2: 고랭지감자:10a당 생산량 (kg) | CW2: 고랭지감자:생산량 (톤) | CX2: 가을감자:면적 (ha) | CY2: 가을감자:10a당 생산량 (kg) | CZ2: 가을감자:생산량 (톤) | DA2: 합계:면적 (ha) | DB2: 합계:생산량 (톤) | DC2: 고구마:면적 (ha) | DD2: 고구마:10a당 생산량 (kg) | DE2: 고구마:생산량 (톤) | DF2: 감자:면적 (ha) | DG2: 감자:10a당 생산량 (kg) | DH2: 감자:생산량 (톤) | DI2: 일반봄감자:면적 (ha) | DJ2: 일반봄감자:10a당 생산량 (kg) | DK2: 일반봄감자:생산량 (톤) | DL2: 고랭지감자:면적 (ha) | DM2: 고랭지감자:10a당 생산량 (kg) | DN2: 고랭지감자:생산량 (톤) | DO2: 가을감자:면적 (ha) | DP2: 가을감자:10a당 생산량 (kg) | DQ2: 가을감자:생산량 (톤) | DR2: 합계:면적 (ha) | DS2: 합계:생산량 (톤) | DT2: 고구마:면적 (ha) | DU2: 고구마:10a당 생산량 (kg) | DV2: 고구마:생산량 (톤) | DW2: 감자:면적 (ha) | DX2: 감자:10a당 생산량 (kg) | DY2: 감자:생산량 (톤) | DZ2: 일반봄감자:면적 (ha) | EA2: 일반봄감자:10a당 생산량 (kg) | EB2: 일반봄감자:생산량 (톤) | EC2: 고랭지감자:면적 (ha) | ED2: 고랭지감자:10a당 생산량 (kg) | EE2: 고랭지감자:생산량 (톤) | EF2: 가을감자:면적 (ha) | EG2: 가을감자:10a당 생산량 (kg) | EH2: 가을감자:생산량 (톤) | EI2: 합계:면적 (ha) | EJ2: 합계:생산량 (톤) | EK2: 고구마:면적 (ha) | EL2: 고구마:10a당 생산량 (kg) | EM2: 고구마:생산량 (톤) | EN2: 감자:면적 (ha) | EO2: 감자:10a당 생산량 (kg) | EP2: 감자:생산량 (톤) | EQ2: 일반봄감자:면적 (ha) | ER2: 일반봄감자:10a당 생산량 (kg) | ES2: 일반봄감자:생산량 (톤) | ET2: 고랭지감자:면적 (ha) | EU2: 고랭지감자:10a당 생산량 (kg) | EV2: 고랭지감자:생산량 (톤) | EW2: 가을감자:면적 (ha) | EX2: 가을감자:10a당 생산량 (kg) | EY2: 가을감자:생산량 (톤) | EZ2: 합계:면적 (ha) | FA2: 합계:생산량 (톤) | FB2: 고구마:면적 (ha) | FC2: 고구마:10a당 생산량 (kg) | FD2: 고구마:생산량 (톤) | FE2: 감자:면적 (ha) | FF2: 감자:10a당 생산량 (kg) | FG2: 감자:생산량 (톤) | FH2: 일반봄감자:면적 (ha) | FI2: 일반봄감자:10a당 생산량 (kg) | FJ2: 일반봄감자:생산량 (톤) | FK2: 고랭지감자:면적 (ha) | FL2: 고랭지감자:10a당 생산량 (kg) | FM2: 고랭지감자:생산량 (톤) | FN2: 가을감자:면적 (ha) | FO2: 가을감자:10a당 생산량 (kg) | FP2: 가을감자:생산량 (톤) | FQ2: 합계:면적 (ha) | FR2: 합계:생산량 (톤) | FS2: 고구마:면적 (ha) | FT2: 고구마:10a당 생산량 (kg) | FU2: 고구마:생산량 (톤) | FV2: 감자:면적 (ha) | FW2: 감자:10a당 생산량 (kg) | FX2: 감자:생산량 (톤) | FY2: 일반봄감자:면적 (ha) | FZ2: 일반봄감자:10a당 생산량 (kg) | GA2: 일반봄감자:생산량 (톤) | GB2: 고랭지감자:면적 (ha) | GC2: 고랭지감자:10a당 생산량 (kg) | GD2: 고랭지감자:생산량 (톤) | GE2: 가을감자:면적 (ha) | GF2: 가을감자:10a당 생산량 (kg) | GG2: 가을감자:생산량 (톤) | GH2: 합계:면적 (ha) | GI2: 합계:생산량 (톤) | GJ2: 고구마:면적 (ha) | GK2: 고구마:10a당 생산량 (kg) | GL2: 고구마:생산량 (톤) | GM2: 감자:면적 (ha) | GN2: 감자:10a당 생산량 (kg) | GO2: 감자:생산량 (톤) | GP2: 일반봄감자:면적 (ha) | GQ2: 일반봄감자:10a당 생산량 (kg) | GR2: 일반봄감자:생산량 (톤) | GS2: 고랭지감자:면적 (ha) | GT2: 고랭지감자:10a당 생산량 (kg) | GU2: 고랭지감자:생산량 (톤) | GV2: 가을감자:면적 (ha) | GW2: 가을감자:10a당 생산량 (kg) | GX2: 가을감자:생산량 (톤) | GY2: 합계:면적 (ha) | GZ2: 합계:생산량 (톤) | HA2: 고구마:면적 (ha) | HB2: 고구마:10a당 생산량 (kg) | HC2: 고구마:생산량 (톤) | HD2: 감자:면적 (ha) | HE2: 감자:10a당 생산량 (kg) | HF2: 감자:생산량 (톤) | HG2: 일반봄감자:면적 (ha) | HH2: 일반봄감자:10a당 생산량 (kg) | HI2: 일반봄감자:생산량 (톤) | HJ2: 고랭지감자:면적 (ha) | HK2: 고랭지감자:10a당 생산량 (kg) | HL2: 고랭지감자:생산량 (톤) | HM2: 가을감자:면적 (ha) | HN2: 가을감자:10a당 생산량 (kg) | HO2: 가을감자:생산량 (톤) | HP2: 합계:면적 (ha) | HQ2: 합계:생산량 (톤) | HR2: 고구마:면적 (ha) | HS2: 고구마:10a당 생산량 (kg) | HT2: 고구마:생산량 (톤) | HU2: 감자:면적 (ha) | HV2: 감자:10a당 생산량 (kg) | HW2: 감자:생산량 (톤) | HX2: 일반봄감자:면적 (ha) | HY2: 일반봄감자:10a당 생산량 (kg) | HZ2: 일반봄감자:생산량 (톤) | IA2: 고랭지감자:면적 (ha) | IB2: 고랭지감자:10a당 생산량 (kg) | IC2: 고랭지감자:생산량 (톤) | ID2: 가을감자:면적 (ha) | IE2: 가을감자:10a당 생산량 (kg) | IF2: 가을감자:생산량 (톤) | IG2: 합계:면적 (ha) | IH2: 합계:생산량 (톤) | II2: 고구마:면적 (ha) | IJ2: 고구마:10a당 생산량 (kg) | IK2: 고구마:생산량 (톤) | IL2: 감자:면적 (ha) | IM2: 감자:10a당 생산량 (kg) | IN2: 감자:생산량 (톤) | IO2: 일반봄감자:면적 (ha) | IP2: 일반봄감자:10a당 생산량 (kg) | IQ2: 일반봄감자:생산량 (톤) | IR2: 고랭지감자:면적 (ha) | IS2: 고랭지감자:10a당 생산량 (kg) | IT2: 고랭지감자:생산량 (톤) | IU2: 가을감자:면적 (ha) | IV2: 가을감자:10a당 생산량 (kg) | IW2: 가을감자:생산량 (톤) | IX2: 합계:면적 (ha) | IY2: 합계:생산량 (톤) | IZ2: 고구마:면적 (ha) | JA2: 고구마:10a당 생산량 (kg) | JB2: 고구마:생산량 (톤) | JC2: 감자:면적 (ha) | JD2: 감자:10a당 생산량 (kg) | JE2: 감자:생산량 (톤) | JF2: 일반봄감자:면적 (ha) | JG2: 일반봄감자:10a당 생산량 (kg) | JH2: 일반봄감자:생산량 (톤) | JI2: 고랭지감자:면적 (ha) | JJ2: 고랭지감자:10a당 생산량 (kg) | JK2: 고랭지감자:생산량 (톤) | JL2: 가을감자:면적 (ha) | JM2: 가을감자:10a당 생산량 (kg) | JN2: 가을감자:생산량 (톤) | JO2: 합계:면적 (ha) | JP2: 합계:생산량 (톤) | JQ2: 고구마:면적 (ha) | JR2: 고구마:10a당 생산량 (kg) | JS2: 고구마:생산량 (톤) | JT2: 감자:면적 (ha) | JU2: 감자:10a당 생산량 (kg) | JV2: 감자:생산량 (톤) | JW2: 일반봄감자:면적 (ha) | JX2: 일반봄감자:10a당 생산량 (kg) | JY2: 일반봄감자:생산량 (톤) | JZ2: 고랭지감자:면적 (ha) | KA2: 고랭지감자:10a당 생산량 (kg) | KB2: 고랭지감자:생산량 (톤) | KC2: 가을감자:면적 (ha) | KD2: 가을감자:10a당 생산량 (kg) | KE2: 가을감자:생산량 (톤) | KF2: 합계:면적 (ha) | KG2: 합계:생산량 (톤) | KH2: 고구마:면적 (ha) | KI2: 고구마:10a당 생산량 (kg) | KJ2: 고구마:생산량 (톤) | KK2: 감자:면적 (ha) | KL2: 감자:10a당 생산량 (kg) | KM2: 감자:생산량 (톤) | KN2: 일반봄감자:면적 (ha) | KO2: 일반봄감자:10a당 생산량 (kg) | KP2: 일반봄감자:생산량 (톤) | KQ2: 고랭지감자:면적 (ha) | KR2: 고랭지감자:10a당 생산량 (kg) | KS2: 고랭지감자:생산량 (톤) | KT2: 가을감자:면적 (ha) | KU2: 가을감자:10a당 생산량 (kg) | KV2: 가을감자:생산량 (톤) | KW2: 합계:면적 (ha) | KX2: 합계:생산량 (톤) | KY2: 고구마:면적 (ha) | KZ2: 고구마:10a당 생산량 (kg) | LA2: 고구마:생산량 (톤) | LB2: 감자:면적 (ha) | LC2: 감자:10a당 생산량 (kg) | LD2: 감자:생산량 (톤) | LE2: 일반봄감자:면적 (ha) | LF2: 일반봄감자:10a당 생산량 (kg) | LG2: 일반봄감자:생산량 (톤) | LH2: 고랭지감자:면적 (ha) | LI2: 고랭지감자:10a당 생산량 (kg) | LJ2: 고랭지감자:생산량 (톤) | LK2: 가을감자:면적 (ha) | LL2: 가을감자:10a당 생산량 (kg) | LM2: 가을감자:생산량 (톤) | LN2: 합계:면적 (ha) | LO2: 합계:생산량 (톤) | LP2: 고구마:면적 (ha) | LQ2: 고구마:10a당 생산량 (kg) | LR2: 고구마:생산량 (톤) | LS2: 감자:면적 (ha) | LT2: 감자:10a당 생산량 (kg) | LU2: 감자:생산량 (톤) | LV2: 일반봄감자:면적 (ha) | LW2: 일반봄감자:10a당 생산량 (kg) | LX2: 일반봄감자:생산량 (톤) | LY2: 고랭지감자:면적 (ha) | LZ2: 고랭지감자:10a당 생산량 (kg) | MA2: 고랭지감자:생산량 (톤) | MB2: 가을감자:면적 (ha) | MC2: 가을감자:10a당 생산량 (kg) | MD2: 가을감자:생산량 (톤) | ME2: 합계:면적 (ha) | MF2: 합계:생산량 (톤) | MG2: 고구마:면적 (ha) | MH2: 고구마:10a당 생산량 (kg) | MI2: 고구마:생산량 (톤) | MJ2: 감자:면적 (ha) | MK2: 감자:10a당 생산량 (kg) | ML2: 감자:생산량 (톤) | MM2: 일반봄감자:면적 (ha) | MN2: 일반봄감자:10a당 생산량 (kg) | MO2: 일반봄감자:생산량 (톤) | MP2: 고랭지감자:면적 (ha) | MQ2: 고랭지감자:10a당 생산량 (kg) | MR2: 고랭지감자:생산량 (톤) | MS2: 가을감자:면적 (ha) | MT2: 가을감자:10a당 생산량 (kg) | MU2: 가을감자:생산량 (톤) | MV2: 합계:면적 (ha) | MW2: 합계:생산량 (톤) | MX2: 고구마:면적 (ha) | MY2: 고구마:10a당 생산량 (kg) | MZ2: 고구마:생산량 (톤) | NA2: 감자:면적 (ha) | NB2: 감자:10a당 생산량 (kg) | NC2: 감자:생산량 (톤) | ND2: 일반봄감자:면적 (ha) | NE2: 일반봄감자:10a당 생산량 (kg) | NF2: 일반봄감자:생산량 (톤) | NG2: 고랭지감자:면적 (ha) | NH2: 고랭지감자:10a당 생산량 (kg) | NI2: 고랭지감자:생산량 (톤) | NJ2: 가을감자:면적 (ha) | NK2: 가을감자:10a당 생산량 (kg) | NL2: 가을감자:생산량 (톤)
A3: 전국 | B3: 소계 | C3: 49906 | D3: 1176741 | E3: 17178 | F3: 1645 | G3: 282526 | H3: 32728 | I3: 2732 | J3: 894215 | K3: 20035 | L3: 2767 | M3: 554467 | N3: 4385 | O3: 3517 | P3: 154229 | Q3: 8308 | R3: 2233 | S3: 185519 | T3: 40625 | U3: 916927 | V3: 16668 | W3: 1715 | X3: 285841 | Y3: 23957 | Z3: 2634 | AA3: 631086 | AB3: 14960 | AC3: 2799 | AD3: 418658 | AE3: 3971 | AF3: 2404 | AG3: 95443 | AH3: 5026 | AI3: 2328 | AJ3: 116985 | AK3: 41514 | AL3: 926665 | AM3: 21093 | AN3: 1670 | AO3: 352269 | AP3: 20421 | AQ3: 2813 | AR3: 574396 | AS3: 13033 | AT3: 2818 | AU3: 367277 | AV3: 3202 | AW3: 3516 | AX3: 112577 | AY3: 4186 | AZ3: 2259 | BA3: 94542 | BB3: 39991 | BC3: 933943 | BD3: 19451 | BE3: 1693 | BF3: 329351 | BG3: 20540 | BH3: 2943 | BI3: 604592 | BJ3: 13048 | BK3: 2930 | BL3: 382369 | BM3: 3364 | BN3: 3650 | BO3: 122781 | BP3: 4128 | BQ3: 2409 | BR3: 99442 | BS3: 42314 | BT3: 941714 | BU3: 20918 | BV3: 1676 | BW3: 350661 | BX3: 21396 | BY3: 2762 | BZ3: 591053 | CA3: 14198 | CB3: 2778 | CC3: 394418 | CD3: 3322 | CE3: 3487 | CF3: 115842 | CG3: 3876 | CH3: 2084 | CI3: 80793 | CJ3: 44113 | CK3: 915637 | CL3: 19200 | CM3: 1557 | CN3: 298930 | CO3: 24913 | CP3: 2475 | CQ3: 616707 | CR3: 16302 | CS3: 2415 | CT3: 393632 | CU3: 3801 | CV3: 3668 | CW3: 139423 | CX3: 4810 | CY3: 1739 | CZ3: 83652 | DA3: 44844 | DB3: 877486 | DC3: 18040 | DD3: 1415 | DE3: 255284 | DF3: 26804 | DG3: 2321 | DH3: 622202 | DI3: 19126 | DJ3: 2392 | DK3: 457584 | DL3: 3784 | DM3: 2509 | DN3: 94944 | DO3: 3894 | DP3: 1789 | DQ3: 69674 | DR3: 47927 | DS3: 950202 | DT3: 22997 | DU3: 1490 | DV3: 342668 | DW3: 24930 | DX3: 2437 | DY3: 607534 | DZ3: 17424 | EA3: 2396 | EB3: 417433 | EC3: 3793 | ED3: 3332 | EE3: 126371 | EF3: 3713 | EG3: 1716 | EH3: 63730 | EI3: 49637 | EJ3: 1056954 | EK3: 22207 | EL3: 1484 | EM3: 329516 | EN3: 27430 | EO3: 2652 | EP3: 727438 | EQ3: 20977 | ER3: 2722 | ES3: 571024 | ET3: 3751 | EU3: 2963 | EV3: 111125 | EW3: 2702 | EX3: 1676 | EY3: 45289 | EZ3: 41987 | FA3: 912603 | FB3: 20515 | FC3: 1570 | FD3: 322071 | FE3: 21472 | FF3: 2750 | FG3: 590532 | FH3: 15596 | FI3: 2772 | FJ3: 432342 | FK3: 2975 | FL3: 3647 | FM3: 108500 | FN3: 2901 | FO3: 1713 | FP3: 49690 | FQ3: 39591 | FR3: 832393 | FS3: 19357 | FT3: 1522 | FU3: 294655 | FV3: 20234 | FW3: 2658 | FX3: 537738 | FY3: 14545 | FZ3: 2526 | GA3: 367363 | GB3: 3403 | GC3: 3875 | GD3: 131867 | GE3: 2286 | GF3: 1685 | GG3: 38508 | GH3: 45151 | GI3: 896895 | GJ3: 23151 | GK3: 1474 | GL3: 341225 | GM3: 22000 | GN3: 2526 | GO3: 555670 | GP3: 15259 | GQ3: 2580 | GR3: 393670 | GS3: 3579 | GT3: 3407 | GU3: 121927 | GV3: 3162 | GW3: 1267 | GX3: 40073 | GY3: 42658 | GZ3: 791715 | HA3: 21684 | HB3: 1499 | HC3: 324960 | HD3: 20974 | HE3: 2225 | HF3: 466755 | HG3: 14943 | HH3: 2152 | HI3: 321518 | HJ3: 3244 | HK3: 3048 | HL3: 98895 | HM3: 2787 | HN3: 1663 | HO3: 46342 | HP3: 44350 | HQ3: 853369 | HR3: 20948 | HS3: 1457 | HT3: 305304 | HU3: 23402 | HV3: 2342 | HW3: 548065 | HX3: 15819 | HY3: 2435 | HZ3: 385244 | IA3: 3462 | IB3: 2652 | IC3: 91811 | ID3: 4121 | IE3: 1723 | IF3: 71010 | IG3: 48771 | IH3: 1058743 | II3: 21941 | IJ3: 1679 | IK3: 368324 | IL3: 26829 | IM3: 2573 | IN3: 690419 | IO3: 18150 | IP3: 2567 | IQ3: 465948 | IR3: 3844 | IS3: 3634 | IT3: 139676 | IU3: 4835 | IV3: 1754 | IW3: 84794 | IX3: 45861 | IY3: 883121 | IZ3: 22262 | JA3: 1482 | JB3: 329927 | JC3: 23599 | JD3: 2344 | JE3: 553194 | JF3: 16339 | JG3: 2303 | JH3: 376349 | JI3: 3390 | JJ3: 3524 | JK3: 119441 | JL3: 3870 | JM3: 1483 | JN3: 57405 | JO3: 44981 | JP3: 903805 | JQ3: 23236 | JR3: 1502 | JS3: 348912 | JT3: 21745 | JU3: 2552 | JV3: 554893 | JW3: 14266 | JX3: 2661 | JY3: 379671 | JZ3: 3888 | KA3: 3037 | KB3: 118084 | KC3: 3591 | KD3: 1591 | KE3: 57137 | KF3: 41433 | KG3: 817754 | KH3: 21345 | KI3: 1580 | KJ3: 337153 | KK3: 20088 | KL3: 2392 | KM3: 480601 | KN3: 13017 | KO3: 2329 | KP3: 303211 | KQ3: 3495 | KR3: 3562 | KS3: 124484 | KT3: 3576 | KU3: 1479 | KV3: 52906 | KW3: 40988 | KX3: 850007 | KY3: 18463 | KZ3: 1623 | LA3: 299714 | LB3: 22525 | LC3: 2443 | LD3: 550293 | LE3: 14699 | LF3: 2436 | LG3: 358022 | LH3: 3835 | LI3: 3304 | LJ3: 126702 | LK3: 3992 | LL3: 1643 | LM3: 65568 | LN3: 41701 | LO3: 898360 | LP3: 17732 | LQ3: 1722 | LR3: 305343 | LS3: 23969 | LT3: 2474 | LU3: 593017 | LV3: 15521 | LW3: 2562 | LX3: 397613 | LY3: 3928 | LZ3: 3218 | MA3: 126399 | MB3: 4520 | MC3: 1527 | MD3: 69005 | ME3: - | MF3: - | MG3: - | MH3: - | MI3: - | MJ3: - | MK3: - | ML3: - | MM3: 14927 | MN3: 2383 | MO3: 355698 | MP3: 3605 | MQ3: 3171 | MR3: 114307 | MS3: - | MT3: - | MU3: - | MV3: - | MW3: - | MX3: - | MY3: - | MZ3: - | NA3: - | NB3: - | NC3: - | ND3: 14897 | NE3: 2424 | NF3: 361167 | NG3: - | NH3: - | NI3: - | NJ3: - | NK3: - | NL3: -
A4: 서울특별시 | B4: 소계 | C4: 29 | D4: 548 | E4: 19 | F4: 1590 | G4: 302 | H4: 10 | I4: 2460 | J4: 246 | K4: 10 | L4: 2456 | M4: 246 | N4: 0 | O4: 0 | P4: 0 | Q4: 0 | R4: 0 | S4: 0 | T4: 34 | U4: 745 | V4: 19 | W4: 1684 | X4: 320 | Y4: 15 | Z4: 2833 | AA4: 425 | AB4: 15 | AC4: 2831 | AD4: 425 | AE4: 0 | AF4: 0 | AG4: 0 | AH4: 0 | AI4: 0 | AJ4: 0 | AK4: 34 | AL4: 673 | AM4: 24 | AN4: 1684 | AO4: 404 | AP4: 10 | AQ4: 2690 | AR4: 269 | AS4: 9 | AT4: 2685 | AU4: 242 | AV4: 0 | AW4: 0 | AX4: 0 | AY4: 1 | AZ4: 2700 | BA4: 27 | BB4: 33 | BC4: 719 | BD4: 21 | BE4: 1782 | BF4: 374 | BG4: 12 | BH4: 2875 | BI4: 345 | BJ4: 12 | BK4: 2872 | BL4: 345 | BM4: 0 | BN4: 0 | BO4: 0 | BP4: 0 | BQ4: 0 | BR4: 0 | BS4: 32 | BT4: 699 | BU4: 18 | BV4: 1628 | BW4: 293 | BX4: 14 | BY4: 2900 | BZ4: 406 | CA4: 14 | CB4: 2899 | CC4: 406 | CD4: 0 | CE4: 0 | CF4: 0 | CG4: 0 | CH4: 0 | CI4: 0 | CJ4: 20 | CK4: 451 | CL4: 7 | CM4: 1429 | CN4: 100 | CO4: 13 | CP4: 2700 | CQ4: 351 | CR4: 12 | CS4: 2731 | CT4: 328 | CU4: 0 | CV4: 0 | CW4: 0 | CX4: 1 | CY4: 2253 | CZ4: 23 | DA4: 28 | DB4: 566 | DC4: 7 | DD4: 1415 | DE4: 99 | DF4: 21 | DG4: 2224 | DH4: 467 | DI4: 4 | DJ4: 2273 | DK4: 91 | DL4: 0 | DM4: 0 | DN4: 0 | DO4: 17 | DP4: 2214 | DQ4: 376 | DR4: 22 | DS4: 352 | DT4: 15 | DU4: 1414 | DV4: 212 | DW4: 7 | DX4: 2000 | DY4: 140 | DZ4: 7 | EA4: 2004 | EB4: 140 | EC4: 0 | ED4: 0 | EE4: 0 | EF4: 0 | EG4: 0 | EH4: 0 | EI4: 35 | EJ4: 597 | EK4: 27 | EL4: 1425 | EM4: 385 | EN4: 8 | EO4: 2650 | EP4: 212 | EQ4: 8 | ER4: 2650 | ES4: 212 | ET4: 0 | EU4: 0 | EV4: 0 | EW4: 0 | EX4: 0 | EY4: 0 | EZ4: 30 | FA4: 531 | FB4: 22 | FC4: 1420 | FD4: 312 | FE4: 8 | FF4: 2738 | FG4: 219 | FH4: 7 | FI4: 2888 | FJ4: 202 | FK4: 0 | FL4: 0 | FM4: 0 | FN4: 1 | FO4: 1666 | FP4: 17 | FQ4: 19 | FR4: 338 | FS4: 13 | FT4: 1571 | FU4: 204 | FV4: 6 | FW4: 2233 | FX4: 134 | FY4: 6 | FZ4: 2226 | GA4: 134 | GB4: 0 | GC4: 0 | GD4: 0 | GE4: 0 | GF4: 0 | GG4: 0 | GH4: 12 | GI4: 259 | GJ4: 6 | GK4: 1392 | GL4: 84 | GM4: 6 | GN4: 2917 | GO4: 175 | GP4: 6 | GQ4: 2908 | GR4: 175 | GS4: 0 | GT4: 0 | GU4: 0 | GV4: 0 | GW4: 0 | GX4: 0 | GY4: 15 | GZ4: 216 | HA4: 9 | HB4: 1210 | HC4: 110 | HD4: 6 | HE4: 1727 | HF4: 106 | HG4: 6 | HH4: 1726 | HI4: 105 | HJ4: 0 | HK4: 0 | HL4: 0 | HM4: 0 | HN4: 1771 | HO4: 1 | HP4: 12 | HQ4: 226 | HR4: 6 | HS4: 1312 | HT4: 78 | HU4: 6 | HV4: 2439 | HW4: 148 | HX4: 6 | HY4: 2454 | HZ4: 148 | IA4: 0 | IB4: 0 | IC4: 0 | ID4: 0 | IE4: 1458 | IF4: 0 | IG4: 12 | IH4: 228 | II4: 7 | IJ4: 1455 | IK4: 106 | IL4: 5 | IM4: 2462 | IN4: 122 | IO4: 5 | IP4: 2560 | IQ4: 117 | IR4: 0 | IS4: 0 | IT4: 0 | IU4: 0 | IV4: 1229 | IW4: 5 | IX4: 13 | IY4: 203 | IZ4: 6 | JA4: 400 | JB4: 23 | JC4: 7 | JD4: 2460 | JE4: 180 | JF4: 7 | JG4: 2485 | JH4: 177 | JI4: 0 | JJ4: 0 | JK4: 0 | JL4: 0 | JM4: 1327 | JN4: 3 | JO4: 22 | JP4: 478 | JQ4: 12 | JR4: 1282 | JS4: 160 | JT4: 9 | JU4: 3348 | JV4: 318 | JW4: 9 | JX4: 3348 | JY4: 318 | JZ4: 0 | KA4: 0 | KB4: 0 | KC4: 0 | KD4: 0 | KE4: 0 | KF4: 25 | KG4: 428 | KH4: 15 | KI4: 1648 | KJ4: 243 | KK4: 10 | KL4: 1850 | KM4: 185 | KN4: 10 | KO4: 1857 | KP4: 184 | KQ4: 0 | KR4: 0 | KS4: 0 | KT4: 0 | KU4: 1089 | KV4: 1 | KW4: 23 | KX4: 448 | KY4: 11 | KZ4: 1407 | LA4: 155 | LB4: 12 | LC4: 2370 | LD4: 293 | LE4: 12 | LF4: 2353 | LG4: 283 | LH4: 0 | LI4: 0 | LJ4: 0 | LK4: 0 | LL4: 2982 | LM4: 10 | LN4: 28 | LO4: 619 | LP4: 12 | LQ4: 1490 | LR4: 180 | LS4: 16 | LT4: 2690 | LU4: 439 | LV4: 16 | LW4: 2690 | LX4: 439 | LY4: - | LZ4: - | MA4: - | MB4: - | MC4: - | MD4: - | ME4: - | MF4: - | MG4: - | MH4: - | MI4: - | MJ4: - | MK4: - | ML4: - | MM4: 8 | MN4: 3424 | MO4: 280 | MP4: - | MQ4: - | MR4: - | MS4: - | MT4: - | MU4: - | MV4: - | MW4: - | MX4: - | MY4: - | MZ4: - | NA4: - | NB4: - | NC4: - | ND4: 9 | NE4: 2310 | NF4: 215 | NG4: - | NH4: - | NI4: - | NJ4: - | NK4: - | NL4: -
A5: 전남광주통합특별시 | B5: 소계 | C5: - | D5: - | E5: - | F5: - | G5: - | H5: - | I5: - | J5: - | K5: - | L5: - | M5: - | N5: - | O5: - | P5: - | Q5: - | R5: - | S5: - | T5: - | U5: - | V5: - | W5: - | X5: - | Y5: - | Z5: - | AA5: - | AB5: - | AC5: - | AD5: - | AE5: - | AF5: - | AG5: - | AH5: - | AI5: - | AJ5: - | AK5: - | AL5: - | AM5: - | AN5: - | AO5: - | AP5: - | AQ5: - | AR5: - | AS5: - | AT5: - | AU5: - | AV5: - | AW5: - | AX5: - | AY5: - | AZ5: - | BA5: - | BB5: - | BC5: - | BD5: - | BE5: - | BF5: - | BG5: - | BH5: - | BI5: - | BJ5: - | BK5: - | BL5: - | BM5: - | BN5: - | BO5: - | BP5: - | BQ5: - | BR5: - | BS5: - | BT5: - | BU5: - | BV5: - | BW5: - | BX5: - | BY5: - | BZ5: - | CA5: - | CB5: - | CC5: - | CD5: - | CE5: - | CF5: - | CG5: - | CH5: - | CI5: - | CJ5: - | CK5: - | CL5: - | CM5: - | CN5: - | CO5: - | CP5: - | CQ5: - | CR5: - | CS5: - | CT5: - | CU5: - | CV5: - | CW5: - | CX5: - | CY5: - | CZ5: - | DA5: - | DB5: - | DC5: - | DD5: - | DE5: - | DF5: - | DG5: - | DH5: - | DI5: - | DJ5: - | DK5: - | DL5: - | DM5: - | DN5: - | DO5: - | DP5: - | DQ5: - | DR5: - | DS5: - | DT5: - | DU5: - | DV5: - | DW5: - | DX5: - | DY5: - | DZ5: - | EA5: - | EB5: - | EC5: - | ED5: - | EE5: - | EF5: - | EG5: - | EH5: - | EI5: - | EJ5: - | EK5: - | EL5: - | EM5: - | EN5: - | EO5: - | EP5: - | EQ5: - | ER5: - | ES5: - | ET5: - | EU5: - | EV5: - | EW5: - | EX5: - | EY5: - | EZ5: - | FA5: - | FB5: - | FC5: - | FD5: - | FE5: - | FF5: - | FG5: - | FH5: - | FI5: - | FJ5: - | FK5: - | FL5: - | FM5: - | FN5: - | FO5: - | FP5: - | FQ5: - | FR5: - | FS5: - | FT5: - | FU5: - | FV5: - | FW5: - | FX5: - | FY5: - | FZ5: - | GA5: - | GB5: - | GC5: - | GD5: - | GE5: - | GF5: - | GG5: - | GH5: - | GI5: - | GJ5: - | GK5: - | GL5: - | GM5: - | GN5: - | GO5: - | GP5: - | GQ5: - | GR5: - | GS5: - | GT5: - | GU5: - | GV5: - | GW5: - | GX5: - | GY5: - | GZ5: - | HA5: - | HB5: - | HC5: - | HD5: - | HE5: - | HF5: - | HG5: - | HH5: - | HI5: - | HJ5: - | HK5: - | HL5: - | HM5: - | HN5: - | HO5: - | HP5: - | HQ5: - | HR5: - | HS5: - | HT5: - | HU5: - | HV5: - | HW5: - | HX5: - | HY5: - | HZ5: - | IA5: - | IB5: - | IC5: - | ID5: - | IE5: - | IF5: - | IG5: - | IH5: - | II5: - | IJ5: - | IK5: - | IL5: - | IM5: - | IN5: - | IO5: - | IP5: - | IQ5: - | IR5: - | IS5: - | IT5: - | IU5: - | IV5: - | IW5: - | IX5: - | IY5: - | IZ5: - | JA5: - | JB5: - | JC5: - | JD5: - | JE5: - | JF5: - | JG5: - | JH5: - | JI5: - | JJ5: - | JK5: - | JL5: - | JM5: - | JN5: - | JO5: - | JP5: - | JQ5: - | JR5: - | JS5: - | JT5: - | JU5: - | JV5: - | JW5: - | JX5: - | JY5: - | JZ5: - | KA5: - | KB5: - | KC5: - | KD5: - | KE5: - | KF5: - | KG5: - | KH5: - | KI5: - | KJ5: - | KK5: - | KL5: - | KM5: - | KN5: - | KO5: - | KP5: - | KQ5: - | KR5: - | KS5: - | KT5: - | KU5: - | KV5: - | KW5: - | KX5: - | KY5: - | KZ5: - | LA5: - | LB5: - | LC5: - | LD5: - | LE5: - | LF5: - | LG5: - | LH5: - | LI5: - | LJ5: - | LK5: - | LL5: - | LM5: - | LN5: - | LO5: - | LP5: - | LQ5: - | LR5: - | LS5: - | LT5: - | LU5: - | LV5: - | LW5: - | LX5: - | LY5: - | LZ5: - | MA5: - | MB5: - | MC5: - | MD5: - | ME5: - | MF5: - | MG5: - | MH5: - | MI5: - | MJ5: - | MK5: - | ML5: - | MM5: - | MN5: - | MO5: - | MP5: - | MQ5: - | MR5: - | MS5: - | MT5: - | MU5: - | MV5: - | MW5: - | MX5: - | MY5: - | MZ5: - | NA5: - | NB5: - | NC5: - | ND5: 2216 | NE5: 2555 | NF5: 56623 | NG5: - | NH5: - | NI5: - | NJ5: - | NK5: - | NL5: -
A6: 전남광주통합특별시 | B6: 광주광역시 | C6: 200 | D6: 4770 | E6: 136 | F6: 2203 | G6: 2996 | H6: 64 | I6: 2772 | J6: 1774 | K6: 30 | L6: 2772 | M6: 832 | N6: 0 | O6: 0 | P6: 0 | Q6: 34 | R6: 2771 | S6: 942 | T6: 110 | U6: 2551 | V6: 58 | W6: 2193 | X6: 1272 | Y6: 52 | Z6: 2460 | AA6: 1279 | AB6: 48 | AC6: 2456 | AD6: 1179 | AE6: 0 | AF6: 0 | AG6: 0 | AH6: 4 | AI6: 2500 | AJ6: 100 | AK6: 132 | AL6: 3092 | AM6: 109 | AN6: 2163 | AO6: 2358 | AP6: 23 | AQ6: 3191 | AR6: 734 | AS6: 14 | AT6: 3194 | AU6: 447 | AV6: 0 | AW6: 0 | AX6: 0 | AY6: 9 | AZ6: 3189 | BA6: 287 | BB6: 133 | BC6: 2931 | BD6: 123 | BE6: 2136 | BF6: 2627 | BG6: 10 | BH6: 3040 | BI6: 304 | BJ6: 10 | BK6: 3036 | BL6: 304 | BM6: 0 | BN6: 0 | BO6: 0 | BP6: 0 | BQ6: 0 | BR6: 0 | BS6: 150 | BT6: 3320 | BU6: 103 | BV6: 2145 | BW6: 2209 | BX6: 47 | BY6: 2364 | BZ6: 1111 | CA6: 32 | CB6: 2351 | CC6: 752 | CD6: 0 | CE6: 0 | CF6: 0 | CG6: 15 | CH6: 2393 | CI6: 359 | CJ6: 132 | CK6: 3006 | CL6: 78 | CM6: 2151 | CN6: 1678 | CO6: 54 | CP6: 2459 | CQ6: 1328 | CR6: 54 | CS6: 2459 | CT6: 1328 | CU6: 0 | CV6: 0 | CW6: 0 | CX6: 0 | CY6: 0 | CZ6: 0 | DA6: 129 | DB6: 2632 | DC6: 92 | DD6: 2144 | DE6: 1972 | DF6: 37 | DG6: 1784 | DH6: 660 | DI6: 28 | DJ6: 1758 | DK6: 492 | DL6: 0 | DM6: 0 | DN6: 0 | DO6: 9 | DP6: 1868 | DQ6: 168 | DR6: 187 | DS6: 3896 | DT6: 167 | DU6: 2110 | DV6: 3524 | DW6: 20 | DX6: 1860 | DY6: 372 | DZ6: 20 | EA6: 1861 | EB6: 372 | EC6: 0 | ED6: 0 | EE6: 0 | EF6: 0 | EG6: 0 | EH6: 0 | EI6: 196 | EJ6: 3620 | EK6: 121 | EL6: 1867 | EM6: 2259 | EN6: 75 | EO6: 1815 | EP6: 1361 | EQ6: 70 | ER6: 1814 | ES6: 1270 | ET6: 0 | EU6: 0 | EV6: 0 | EW6: 5 | EX6: 1818 | EY6: 91 | EZ6: 161 | FA6: 3217 | FB6: 109 | FC6: 2078 | FD6: 2265 | FE6: 52 | FF6: 1831 | FG6: 952 | FH6: 52 | FI6: 1830 | FJ6: 952 | FK6: 0 | FL6: 0 | FM6: 0 | FN6: 0 | FO6: 0 | FP6: 0 | FQ6: 83 | FR6: 1433 | FS6: 67 | FT6: 1721 | FU6: 1153 | FV6: 16 | FW6: 1750 | FX6: 280 | FY6: 14 | FZ6: 1762 | GA6: 247 | GB6: 0 | GC6: 0 | GD6: 0 | GE6: 2 | GF6: 1642 | GG6: 33 | GH6: 143 | GI6: 2946 | GJ6: 82 | GK6: 1914 | GL6: 1569 | GM6: 61 | GN6: 2257 | GO6: 1377 | GP6: 61 | GQ6: 2257 | GR6: 1377 | GS6: 0 | GT6: 0 | GU6: 0 | GV6: 0 | GW6: 0 | GX6: 0 | GY6: 176 | GZ6: 3333 | HA6: 91 | HB6: 1613 | HC6: 1475 | HD6: 84 | HE6: 2208 | HF6: 1858 | HG6: 82 | HH6: 2219 | HI6: 1816 | HJ6: 0 | HK6: 0 | HL6: 0 | HM6: 2 | HN6: 1837 | HO6: 42 | HP6: 131 | HQ6: 2097 | HR6: 85 | HS6: 1580 | HT6: 1348 | HU6: 46 | HV6: 1646 | HW6: 749 | HX6: 44 | HY6: 1642 | HZ6: 719 | IA6: 0 | IB6: 0 | IC6: 0 | ID6: 2 | IE6: 1720 | IF6: 30 | IG6: 116 | IH6: 1844 | II6: 72 | IJ6: 1230 | IK6: 883 | IL6: 44 | IM6: 2174 | IN6: 961 | IO6: 41 | IP6: 2232 | IQ6: 916 | IR6: 0 | IS6: 0 | IT6: 0 | IU6: 3 | IV6: 1411 | IW6: 45 | IX6: 124 | IY6: 1916 | IZ6: 82 | JA6: 1402 | JB6: 1147 | JC6: 42 | JD6: 1842 | JE6: 769 | JF6: 42 | JG6: 1843 | JH6: 767 | JI6: 0 | JJ6: 0 | JK6: 0 | JL6: 0 | JM6: 1403 | JN6: 2 | JO6: 169 | JP6: 2561 | JQ6: 132 | JR6: 1403 | JS6: 1857 | JT6: 37 | JU6: 1917 | JV6: 704 | JW6: 30 | JX6: 2036 | JY6: 608 | JZ6: 0 | KA6: 0 | KB6: 0 | KC6: 7 | KD6: 1397 | KE6: 96 | KF6: 112 | KG6: 1624 | KH6: 89 | KI6: 1394 | KJ6: 1243 | KK6: 23 | KL6: 1679 | KM6: 381 | KN6: 13 | KO6: 1899 | KP6: 237 | KQ6: 0 | KR6: 0 | KS6: 0 | KT6: 10 | KU6: 1406 | KV6: 144 | KW6: 115 | KX6: 1795 | KY6: 90 | KZ6: 1416 | LA6: 1275 | LB6: 25 | LC6: 2099 | LD6: 520 | LE6: 16 | LF6: 2473 | LG6: 397 | LH6: 0 | LI6: 0 | LJ6: 0 | LK6: 9 | LL6: 1412 | LM6: 123 | LN6: 114 | LO6: 1682 | LP6: 54 | LQ6: 1401 | LR6: 762 | LS6: 60 | LT6: 1539 | LU6: 920 | LV6: 46 | LW6: 1571 | LX6: 727 | LY6: - | LZ6: - | MA6: - | MB6: 13 | MC6: 1432 | MD6: 193 | ME6: - | MF6: - | MG6: - | MH6: - | MI6: - | MJ6: - | MK6: - | ML6: - | MM6: 13 | MN6: 2175 | MO6: 290 | MP6: - | MQ6: - | MR6: - | MS6: - | MT6: - | MU6: - | MV6: - | MW6: - | MX6: - | MY6: - | MZ6: - | NA6: - | NB6: - | NC6: - | ND6: 59 | NE6: 2515 | NF6: 1473 | NG6: - | NH6: - | NI6: - | NJ6: - | NK6: - | NL6: -
A7: 전남광주통합특별시 | B7: 전라남도 | C7: 7494 | D7: 158292 | E7: 3475 | F7: 1561 | G7: 54245 | H7: 4019 | I7: 2589 | J7: 104047 | K7: 3193 | L7: 2772 | M7: 88510 | N7: 0 | O7: 0 | P7: 0 | Q7: 826 | R7: 1881 | S7: 15537 | T7: 5894 | U7: 128512 | V7: 3542 | W7: 1876 | X7: 66448 | Y7: 2352 | Z7: 2639 | AA7: 62064 | AB7: 2062 | AC7: 2737 | AD7: 56441 | AE7: 0 | AF7: 0 | AG7: 0 | AH7: 290 | AI7: 1939 | AJ7: 5623 | AK7: 6437 | AL7: 136906 | AM7: 4629 | AN7: 1783 | AO7: 82535 | AP7: 1808 | AQ7: 3007 | AR7: 54371 | AS7: 1518 | AT7: 3194 | AU7: 48487 | AV7: 0 | AW7: 0 | AX7: 0 | AY7: 290 | AZ7: 2029 | BA7: 5884 | BB7: 5664 | BC7: 120255 | BD7: 3834 | BE7: 1744 | BF7: 66865 | BG7: 1830 | BH7: 2917 | BI7: 53390 | BJ7: 1537 | BK7: 3036 | BL7: 46669 | BM7: 0 | BN7: 0 | BO7: 0 | BP7: 293 | BQ7: 2294 | BR7: 6721 | BS7: 6216 | BT7: 132499 | BU7: 4280 | BV7: 1829 | BW7: 78281 | BX7: 1936 | BY7: 2801 | BZ7: 54218 | CA7: 1613 | CB7: 2900 | CC7: 46779 | CD7: 0 | CE7: 0 | CF7: 0 | CG7: 323 | CH7: 2303 | CI7: 7439 | CJ7: 6663 | CK7: 133545 | CL7: 3981 | CM7: 1876 | CN7: 74684 | CO7: 2682 | CP7: 2195 | CQ7: 58861 | CR7: 2137 | CS7: 2246 | CT7: 47994 | CU7: 0 | CV7: 0 | CW7: 0 | CX7: 545 | CY7: 1994 | CZ7: 10867 | DA7: 6350 | DB7: 125149 | DC7: 3818 | DD7: 1838 | DE7: 70175 | DF7: 2532 | DG7: 2171 | DH7: 54974 | DI7: 2042 | DJ7: 2251 | DK7: 45963 | DL7: 0 | DM7: 0 | DN7: 0 | DO7: 490 | DP7: 1839 | DQ7: 9011 | DR7: 6989 | DS7: 134824 | DT7: 4626 | DU7: 1792 | DV7: 82898 | DW7: 2363 | DX7: 2197 | DY7: 51926 | DZ7: 2051 | EA7: 2244 | EB7: 46035 | EC7: 0 | ED7: 0 | EE7: 0 | EF7: 312 | EG7: 1888 | EH7: 5891 | EI7: 7361 | EJ7: 144068 | EK7: 4727 | EL7: 1544 | EM7: 72985 | EN7: 2634 | EO7: 2699 | EP7: 71083 | EQ7: 2293 | ER7: 2830 | ES7: 64884 | ET7: 0 | EU7: 0 | EV7: 0 | EW7: 341 | EX7: 1818 | EY7: 6199 | EZ7: 6647 | FA7: 136351 | FB7: 4214 | FC7: 1750 | FD7: 73745 | FE7: 2433 | FF7: 2573 | FG7: 62606 | FH7: 2226 | FI7: 2639 | FJ7: 58754 | FK7: 0 | FL7: 0 | FM7: 0 | FN7: 207 | FO7: 1861 | FP7: 3852 | FQ7: 6574 | FR7: 132017 | FS7: 4315 | FT7: 1733 | FU7: 74779 | FV7: 2259 | FW7: 2534 | FX7: 57238 | FY7: 1942 | FZ7: 2619 | GA7: 50869 | GB7: 0 | GC7: 0 | GD7: 0 | GE7: 317 | GF7: 2009 | GG7: 6369 | GH7: 7557 | GI7: 135077 | GJ7: 5391 | GK7: 1546 | GL7: 83345 | GM7: 2166 | GN7: 2388 | GO7: 51732 | GP7: 1855 | GQ7: 2489 | GR7: 46165 | GS7: 0 | GT7: 0 | GU7: 0 | GV7: 311 | GW7: 1790 | GX7: 5567 | GY7: 7007 | GZ7: 133952 | HA7: 4884 | HB7: 1775 | HC7: 86685 | HD7: 2123 | HE7: 2226 | HF7: 47267 | HG7: 1845 | HH7: 2285 | HI7: 42156 | HJ7: 0 | HK7: 0 | HL7: 0 | HM7: 278 | HN7: 1837 | HO7: 5111 | HP7: 7865 | HQ7: 155713 | HR7: 5114 | HS7: 1855 | HT7: 94862 | HU7: 2751 | HV7: 2212 | HW7: 60851 | HX7: 2062 | HY7: 2376 | HZ7: 48992 | IA7: 0 | IB7: 0 | IC7: 0 | ID7: 689 | IE7: 1720 | IF7: 11859 | IG7: 8777 | IH7: 226364 | II7: 5572 | IJ7: 2477 | IK7: 138011 | IL7: 3205 | IM7: 2757 | IN7: 88353 | IO7: 2273 | IP7: 2691 | IQ7: 61173 | IR7: 0 | IS7: 0 | IT7: 0 | IU7: 932 | IV7: 2916 | IW7: 27180 | IX7: 8428 | IY7: 156044 | IZ7: 5640 | JA7: 1731 | JB7: 97635 | JC7: 2788 | JD7: 2095 | JE7: 58409 | JF7: 2331 | JG7: 2257 | JH7: 52603 | JI7: 0 | JJ7: 0 | JK7: 0 | JL7: 457 | JM7: 1270 | JN7: 5806 | JO7: 8444 | JP7: 158498 | JQ7: 6215 | JR7: 1739 | JS7: 108081 | JT7: 2229 | JU7: 2262 | JV7: 50417 | JW7: 1850 | JX7: 2369 | JY7: 43828 | JZ7: 0 | KA7: 0 | KB7: 0 | KC7: 379 | KD7: 1740 | KE7: 6589 | KF7: 8753 | KG7: 165400 | KH7: 6155 | KI7: 1772 | KJ7: 109065 | KK7: 2598 | KL7: 2169 | KM7: 56335 | KN7: 2050 | KO7: 2266 | KP7: 46461 | KQ7: 0 | KR7: 0 | KS7: 0 | KT7: 548 | KU7: 1803 | KV7: 9874 | KW7: 8832 | KX7: 186886 | KY7: 5532 | KZ7: 2126 | LA7: 117608 | LB7: 3300 | LC7: 2099 | LD7: 69278 | LE7: 2373 | LF7: 2263 | LG7: 53720 | LH7: 0 | LI7: 0 | LJ7: 0 | LK7: 926 | LL7: 1679 | LM7: 15558 | LN7: 8522 | LO7: 182649 | LP7: 5374 | LQ7: 2265 | LR7: 121710 | LS7: 3149 | LT7: 1935 | LU7: 60939 | LV7: 2219 | LW7: 2148 | LX7: 47663 | LY7: - | LZ7: - | MA7: - | MB7: 930 | MC7: 1428 | MD7: 13276 | ME7: - | MF7: - | MG7: - | MH7: - | MI7: - | MJ7: - | MK7: - | ML7: - | MM7: 1909 | MN7: 2197 | MO7: 41933 | MP7: - | MQ7: - | MR7: - | MS7: - | MT7: - | MU7: - | MV7: - | MW7: - | MX7: - | MY7: - | MZ7: - | NA7: - | NB7: - | NC7: - | ND7: 2158 | NE7: 2556 | NF7: 55150 | NG7: - | NH7: - | NI7: - | NJ7: - | NK7: - | NL7: -
A8: 부산광역시 | B8: 소계 | C8: 93 | D8: 2129 | E8: 33 | F8: 1845 | G8: 609 | H8: 60 | I8: 2533 | J8: 1520 | K8: 22 | L8: 2909 | M8: 640 | N8: 0 | O8: 0 | P8: 0 | Q8: 38 | R8: 2316 | S8: 880 | T8: 62 | U8: 1279 | V8: 36 | W8: 1636 | X8: 589 | Y8: 26 | Z8: 2654 | AA8: 690 | AB8: 15 | AC8: 2656 | AD8: 398 | AE8: 0 | AF8: 0 | AG8: 0 | AH8: 11 | AI8: 2655 | AJ8: 292 | AK8: 119 | AL8: 2684 | AM8: 44 | AN8: 1573 | AO8: 692 | AP8: 75 | AQ8: 2656 | AR8: 1992 | AS8: 25 | AT8: 2656 | AU8: 664 | AV8: 0 | AW8: 0 | AX8: 0 | AY8: 50 | AZ8: 2656 | BA8: 1328 | BB8: 95 | BC8: 1459 | BD8: 71 | BE8: 1180 | BF8: 838 | BG8: 24 | BH8: 2588 | BI8: 621 | BJ8: 19 | BK8: 2805 | BL8: 533 | BM8: 0 | BN8: 0 | BO8: 0 | BP8: 5 | BQ8: 1760 | BR8: 88 | BS8: 76 | BT8: 1058 | BU8: 61 | BV8: 1176 | BW8: 717 | BX8: 15 | BY8: 2273 | BZ8: 341 | CA8: 11 | CB8: 2477 | CC8: 272 | CD8: 0 | CE8: 0 | CF8: 0 | CG8: 4 | CH8: 1731 | CI8: 69 | CJ8: 89 | CK8: 1146 | CL8: 77 | CM8: 1144 | CN8: 881 | CO8: 12 | CP8: 2208 | CQ8: 265 | CR8: 12 | CS8: 2209 | CT8: 265 | CU8: 0 | CV8: 0 | CW8: 0 | CX8: 0 | CY8: 0 | CZ8: 0 | DA8: 119 | DB8: 1473 | DC8: 88 | DD8: 1003 | DE8: 883 | DF8: 31 | DG8: 1903 | DH8: 590 | DI8: 31 | DJ8: 1905 | DK8: 590 | DL8: 0 | DM8: 0 | DN8: 0 | DO8: 0 | DP8: 0 | DQ8: 0 | DR8: 142 | DS8: 1652 | DT8: 119 | DU8: 979 | DV8: 1165 | DW8: 23 | DX8: 2117 | DY8: 487 | DZ8: 22 | EA8: 2156 | EB8: 474 | EC8: 0 | ED8: 0 | EE8: 0 | EF8: 1 | EG8: 1303 | EH8: 13 | EI8: 195 | EJ8: 2773 | EK8: 143 | EL8: 1050 | EM8: 1502 | EN8: 52 | EO8: 2444 | EP8: 1271 | EQ8: 36 | ER8: 2927 | ES8: 1054 | ET8: 0 | EU8: 0 | EV8: 0 | EW8: 16 | EX8: 1357 | EY8: 217 | EZ8: 155 | FA8: 1872 | FB8: 133 | FC8: 975 | FD8: 1297 | FE8: 22 | FF8: 2614 | FG8: 575 | FH8: 22 | FI8: 2615 | FJ8: 575 | FK8: 0 | FL8: 0 | FM8: 0 | FN8: 0 | FO8: 0 | FP8: 0 | FQ8: 128 | FR8: 1535 | FS8: 99 | FT8: 888 | FU8: 879 | FV8: 29 | FW8: 2262 | FX8: 656 | FY8: 28 | FZ8: 2291 | GA8: 641 | GB8: 0 | GC8: 0 | GD8: 0 | GE8: 1 | GF8: 1533 | GG8: 15 | GH8: 94 | GI8: 965 | GJ8: 50 | GK8: 877 | GL8: 439 | GM8: 44 | GN8: 1195 | GO8: 526 | GP8: 19 | GQ8: 1970 | GR8: 374 | GS8: 0 | GT8: 0 | GU8: 0 | GV8: 25 | GW8: 606 | GX8: 152 | GY8: 107 | GZ8: 1385 | HA8: 54 | HB8: 949 | HC8: 516 | HD8: 53 | HE8: 1650 | HF8: 869 | HG8: 34 | HH8: 1820 | HI8: 613 | HJ8: 0 | HK8: 0 | HL8: 0 | HM8: 19 | HN8: 1351 | HO8: 256 | HP8: 99 | HQ8: 2167 | HR8: 46 | HS8: 2379 | HT8: 1098 | HU8: 53 | HV8: 2009 | HW8: 1069 | HX8: 38 | HY8: 1877 | HZ8: 718 | IA8: 0 | IB8: 0 | IC8: 0 | ID8: 15 | IE8: 2343 | IF8: 351 | IG8: 121 | IH8: 1509 | II8: 56 | IJ8: 687 | IK8: 387 | IL8: 65 | IM8: 1735 | IN8: 1122 | IO8: 45 | IP8: 2077 | IQ8: 934 | IR8: 0 | IS8: 0 | IT8: 0 | IU8: 20 | IV8: 957 | IW8: 188 | IX8: 151 | IY8: 1816 | IZ8: 51 | JA8: 676 | JB8: 348 | JC8: 100 | JD8: 1475 | JE8: 1468 | JF8: 44 | JG8: 2158 | JH8: 939 | JI8: 0 | JJ8: 0 | JK8: 0 | JL8: 56 | JM8: 944 | JN8: 529 | JO8: 79 | JP8: 1130 | JQ8: 45 | JR8: 723 | JS8: 322 | JT8: 34 | JU8: 2353 | JV8: 808 | JW8: 25 | JX8: 2869 | JY8: 723 | JZ8: 0 | KA8: 0 | KB8: 0 | KC8: 9 | KD8: 935 | KE8: 85 | KF8: 88 | KG8: 1066 | KH8: 50 | KI8: 727 | KJ8: 363 | KK8: 38 | KL8: 1866 | KM8: 703 | KN8: 24 | KO8: 2417 | KP8: 571 | KQ8: 0 | KR8: 0 | KS8: 0 | KT8: 14 | KU8: 941 | KV8: 132 | KW8: 79 | KX8: 972 | KY8: 37 | KZ8: 733 | LA8: 274 | LB8: 42 | LC8: 1672 | LD8: 698 | LE8: 28 | LF8: 2009 | LG8: 563 | LH8: 0 | LI8: 0 | LJ8: 0 | LK8: 14 | LL8: 988 | LM8: 135 | LN8: 82 | LO8: 1511 | LP8: 36 | LQ8: 810 | LR8: 293 | LS8: 46 | LT8: 2659 | LU8: 1218 | LV8: 37 | LW8: 2826 | LX8: 1041 | LY8: - | LZ8: - | MA8: - | MB8: 9 | MC8: 1980 | MD8: 177 | ME8: - | MF8: - | MG8: - | MH8: - | MI8: - | MJ8: - | MK8: - | ML8: - | MM8: 31 | MN8: 2910 | MO8: 897 | MP8: - | MQ8: - | MR8: - | MS8: - | MT8: - | MU8: - | MV8: - | MW8: - | MX8: - | MY8: - | MZ8: - | NA8: - | NB8: - | NC8: - | ND8: 56 | NE8: 1967 | NF8: 1092 | NG8: - | NH8: - | NI8: - | NJ8: - | NK8: - | NL8: -
A9: 대구광역시 | B9: 소계 | C9: 194 | D9: 4062 | E9: 71 | F9: 1507 | G9: 1070 | H9: 123 | I9: 2433 | J9: 2992 | K9: 115 | L9: 2451 | M9: 2819 | N9: 0 | O9: 0 | P9: 0 | Q9: 8 | R9: 2163 | S9: 173 | T9: 183 | U9: 4057 | V9: 64 | W9: 1688 | X9: 1080 | Y9: 119 | Z9: 2502 | AA9: 2977 | AB9: 118 | AC9: 2502 | AD9: 2952 | AE9: 0 | AF9: 0 | AG9: 0 | AH9: 1 | AI9: 2500 | AJ9: 25 | AK9: 164 | AL9: 3380 | AM9: 76 | AN9: 1380 | AO9: 1049 | AP9: 88 | AQ9: 2649 | AR9: 2331 | AS9: 72 | AT9: 2737 | AU9: 1971 | AV9: 0 | AW9: 0 | AX9: 0 | AY9: 16 | AZ9: 2250 | BA9: 360 | BB9: 185 | BC9: 4436 | BD9: 84 | BE9: 1673 | BF9: 1405 | BG9: 101 | BH9: 3001 | BI9: 3031 | BJ9: 101 | BK9: 3001 | BL9: 3031 | BM9: 0 | BN9: 0 | BO9: 0 | BP9: 0 | BQ9: 0 | BR9: 0 | BS9: 203 | BT9: 3646 | BU9: 109 | BV9: 1588 | BW9: 1731 | BX9: 94 | BY9: 2037 | BZ9: 1915 | CA9: 90 | CB9: 2088 | CC9: 1879 | CD9: 0 | CE9: 0 | CF9: 0 | CG9: 4 | CH9: 900 | CI9: 36 | CJ9: 232 | CK9: 3490 | CL9: 120 | CM9: 1276 | CN9: 1531 | CO9: 112 | CP9: 1749 | CQ9: 1959 | CR9: 104 | CS9: 1789 | CT9: 1860 | CU9: 0 | CV9: 0 | CW9: 0 | CX9: 8 | CY9: 1239 | CZ9: 99 | DA9: 200 | DB9: 3829 | DC9: 101 | DD9: 1299 | DE9: 1312 | DF9: 99 | DG9: 2542 | DH9: 2517 | DI9: 99 | DJ9: 2542 | DK9: 2517 | DL9: 0 | DM9: 0 | DN9: 0 | DO9: 0 | DP9: 0 | DQ9: 0 | DR9: 202 | DS9: 4428 | DT9: 96 | DU9: 1255 | DV9: 1205 | DW9: 106 | DX9: 3041 | DY9: 3223 | DZ9: 106 | EA9: 3041 | EB9: 3223 | EC9: 0 | ED9: 0 | EE9: 0 | EF9: 0 | EG9: 0 | EH9: 0 | EI9: 288 | EJ9: 5423 | EK9: 123 | EL9: 1306 | EM9: 1606 | EN9: 165 | EO9: 2313 | EP9: 3817 | EQ9: 148 | ER9: 2349 | ES9: 3477 | ET9: 0 | EU9: 0 | EV9: 0 | EW9: 17 | EX9: 2000 | EY9: 340 | EZ9: 165 | FA9: 2824 | FB9: 82 | FC9: 1009 | FD9: 827 | FE9: 83 | FF9: 2406 | FG9: 1997 | FH9: 74 | FI9: 2504 | FJ9: 1853 | FK9: 0 | FL9: 0 | FM9: 0 | FN9: 9 | FO9: 1600 | FP9: 144 | FQ9: 133 | FR9: 2344 | FS9: 66 | FT9: 1053 | FU9: 695 | FV9: 67 | FW9: 2461 | FX9: 1649 | FY9: 63 | FZ9: 2540 | GA9: 1600 | GB9: 0 | GC9: 0 | GD9: 0 | GE9: 4 | GF9: 1227 | GG9: 49 | GH9: 200 | GI9: 4022 | GJ9: 77 | GK9: 1030 | GL9: 793 | GM9: 123 | GN9: 2625 | GO9: 3229 | GP9: 118 | GQ9: 2637 | GR9: 3111 | GS9: 0 | GT9: 0 | GU9: 0 | GV9: 5 | GW9: 2361 | GX9: 118 | GY9: 179 | GZ9: 2967 | HA9: 78 | HB9: 993 | HC9: 777 | HD9: 100 | HE9: 2184 | HF9: 2190 | HG9: 95 | HH9: 2183 | HI9: 2072 | HJ9: 0 | HK9: 0 | HL9: 0 | HM9: 5 | HN9: 2194 | HO9: 118 | HP9: 119 | HQ9: 1889 | HR9: 58 | HS9: 940 | HT9: 541 | HU9: 61 | HV9: 2199 | HW9: 1348 | HX9: 56 | HY9: 2201 | HZ9: 1231 | IA9: 0 | IB9: 0 | IC9: 0 | ID9: 5 | IE9: 2174 | IF9: 117 | IG9: 151 | IH9: 2040 | II9: 56 | IJ9: 636 | IK9: 357 | IL9: 95 | IM9: 1777 | IN9: 1683 | IO9: 94 | IP9: 1782 | IQ9: 1667 | IR9: 0 | IS9: 0 | IT9: 0 | IU9: 1 | IV9: 1403 | IW9: 16 | IX9: 158 | IY9: 2450 | IZ9: 70 | JA9: 637 | JB9: 448 | JC9: 87 | JD9: 2297 | JE9: 2002 | JF9: 85 | JG9: 2325 | JH9: 1966 | JI9: 0 | JJ9: 0 | JK9: 0 | JL9: 3 | JM9: 1372 | JN9: 36 | JO9: 116 | JP9: 1353 | JQ9: 72 | JR9: 586 | JS9: 420 | JT9: 45 | JU9: 2093 | JV9: 933 | JW9: 44 | JX9: 2096 | JY9: 929 | JZ9: 0 | KA9: 0 | KB9: 0 | KC9: 0 | KD9: 1352 | KE9: 4 | KF9: 98 | KG9: 1385 | KH9: 58 | KI9: 762 | KJ9: 445 | KK9: 40 | KL9: 2366 | KM9: 940 | KN9: 37 | KO9: 2436 | KP9: 902 | KQ9: 0 | KR9: 0 | KS9: 0 | KT9: 3 | KU9: 1402 | KV9: 38 | KW9: 110 | KX9: 1649 | KY9: 41 | KZ9: 1279 | LA9: 519 | LB9: 70 | LC9: 1624 | LD9: 1130 | LE9: 37 | LF9: 1987 | LG9: 732 | LH9: 0 | LI9: 0 | LJ9: 0 | LK9: 33 | LL9: 1215 | LM9: 398 | LN9: 374 | LO9: 9185 | LP9: 71 | LQ9: 1350 | LR9: 957 | LS9: 303 | LT9: 2711 | LU9: 8228 | LV9: 286 | LW9: 2804 | LX9: 8020 | LY9: - | LZ9: - | MA9: - | MB9: 17 | MC9: 1188 | MD9: 208 | ME9: - | MF9: - | MG9: - | MH9: - | MI9: - | MJ9: - | MK9: - | ML9: - | MM9: 256 | MN9: 1991 | MO9: 5096 | MP9: - | MQ9: - | MR9: - | MS9: - | MT9: - | MU9: - | MV9: - | MW9: - | MX9: - | MY9: - | MZ9: - | NA9: - | NB9: - | NC9: - | ND9: 122 | NE9: 2200 | NF9: 2691 | NG9: - | NH9: - | NI9: - | NJ9: - | NK9: - | NL9: -
A10: 인천광역시 | B10: 소계 | C10: 723 | D10: 13905 | E10: 471 | F10: 1714 | G10: 8073 | H10: 252 | I10: 2314 | J10: 5832 | K10: 247 | L10: 2314 | M10: 5716 | N10: 0 | O10: 0 | P10: 0 | Q10: 5 | R10: 2320 | S10: 116 | T10: 679 | U10: 13235 | V10: 482 | W10: 1658 | X10: 7992 | Y10: 197 | Z10: 2661 | AA10: 5243 | AB10: 197 | AC10: 2661 | AD10: 5243 | AE10: 0 | AF10: 0 | AG10: 0 | AH10: 0 | AI10: 0 | AJ10: 0 | AK10: 829 | AL10: 15260 | AM10: 646 | AN10: 1688 | AO10: 10904 | AP10: 183 | AQ10: 2380 | AR10: 4356 | AS10: 182 | AT10: 2380 | AU10: 4332 | AV10: 0 | AW10: 0 | AX10: 0 | AY10: 1 | AZ10: 2400 | BA10: 24 | BB10: 908 | BC10: 18060 | BD10: 709 | BE10: 1720 | BF10: 12195 | BG10: 199 | BH10: 2947 | BI10: 5865 | BJ10: 182 | BK10: 2952 | BL10: 5373 | BM10: 0 | BN10: 0 | BO10: 0 | BP10: 17 | BQ10: 2894 | BR10: 492 | BS10: 1013 | BT10: 20219 | BU10: 794 | BV10: 1701 | BW10: 13506 | BX10: 219 | BY10: 3065 | BZ10: 6713 | CA10: 216 | CB10: 3079 | CC10: 6650 | CD10: 0 | CE10: 0 | CF10: 0 | CG10: 3 | CH10: 2100 | CI10: 63 | CJ10: 908 | CK10: 17356 | CL10: 689 | CM10: 1538 | CN10: 10597 | CO10: 219 | CP10: 3086 | CQ10: 6759 | CR10: 218 | CS10: 3092 | CT10: 6740 | CU10: 0 | CV10: 0 | CW10: 0 | CX10: 1 | CY10: 1900 | CZ10: 19 | DA10: 896 | DB10: 13334 | DC10: 662 | DD10: 895 | DE10: 5925 | DF10: 234 | DG10: 3166 | DH10: 7409 | DI10: 233 | DJ10: 3172 | DK10: 7391 | DL10: 0 | DM10: 0 | DN10: 0 | DO10: 1 | DP10: 1750 | DQ10: 18 | DR10: 1120 | DS10: 15113 | DT10: 887 | DU10: 1156 | DV10: 10254 | DW10: 233 | DX10: 2085 | DY10: 4859 | DZ10: 232 | EA10: 2087 | EB10: 4842 | EC10: 0 | ED10: 0 | EE10: 0 | EF10: 1 | EG10: 1690 | EH10: 17 | EI10: 1124 | EJ10: 20162 | EK10: 894 | EL10: 1559 | EM10: 13937 | EN10: 230 | EO10: 2707 | EP10: 6225 | EQ10: 230 | ER10: 2706 | ES10: 6225 | ET10: 0 | EU10: 0 | EV10: 0 | EW10: 0 | EX10: 0 | EY10: 0 | EZ10: 1140 | FA10: 22664 | FB10: 931 | FC10: 1724 | FD10: 16050 | FE10: 209 | FF10: 3165 | FG10: 6614 | FH10: 207 | FI10: 3184 | FJ10: 6590 | FK10: 0 | FL10: 0 | FM10: 0 | FN10: 2 | FO10: 1202 | FP10: 24 | FQ10: 1002 | FR10: 15055 | FS10: 801 | FT10: 1256 | FU10: 10061 | FV10: 201 | FW10: 2485 | FX10: 4994 | FY10: 198 | FZ10: 2500 | GA10: 4950 | GB10: 0 | GC10: 0 | GD10: 0 | GE10: 3 | GF10: 1450 | GG10: 44 | GH10: 1004 | GI10: 18853 | GJ10: 833 | GK10: 1691 | GL10: 14086 | GM10: 171 | GN10: 2788 | GO10: 4767 | GP10: 166 | GQ10: 2827 | GR10: 4693 | GS10: 0 | GT10: 0 | GU10: 0 | GV10: 5 | GW10: 1479 | GX10: 74 | GY10: 973 | GZ10: 16488 | HA10: 826 | HB10: 1536 | HC10: 12688 | HD10: 147 | HE10: 2583 | HF10: 3800 | HG10: 144 | HH10: 2599 | HI10: 3748 | HJ10: 0 | HK10: 0 | HL10: 0 | HM10: 3 | HN10: 1771 | HO10: 52 | HP10: 840 | HQ10: 11810 | HR10: 680 | HS10: 1054 | HT10: 7165 | HU10: 160 | HV10: 2905 | HW10: 4645 | HX10: 155 | HY10: 2975 | HZ10: 4615 | IA10: 0 | IB10: 0 | IC10: 0 | ID10: 5 | IE10: 626 | IF10: 30 | IG10: 940 | IH10: 14978 | II10: 744 | IJ10: 1501 | IK10: 11163 | IL10: 196 | IM10: 1944 | IN10: 3815 | IO10: 180 | IP10: 2067 | IQ10: 3711 | IR10: 0 | IS10: 0 | IT10: 0 | IU10: 17 | IV10: 622 | IW10: 104 | IX10: 1046 | IY10: 17052 | IZ10: 869 | JA10: 1532 | JB10: 13313 | JC10: 177 | JD10: 2110 | JE10: 3739 | JF10: 174 | JG10: 2148 | JH10: 3728 | JI10: 0 | JJ10: 0 | JK10: 0 | JL10: 4 | JM10: 294 | JN10: 11 | JO10: 884 | JP10: 15693 | JQ10: 711 | JR10: 1510 | JS10: 10729 | JT10: 174 | JU10: 2856 | JV10: 4964 | JW10: 169 | JX10: 2923 | JY10: 4951 | JZ10: 0 | KA10: 0 | KB10: 0 | KC10: 4 | KD10: 303 | KE10: 13 | KF10: 846 | KG10: 13930 | KH10: 698 | KI10: 1494 | KJ10: 10429 | KK10: 148 | KL10: 2366 | KM10: 3501 | KN10: 143 | KO10: 2374 | KP10: 3386 | KQ10: 0 | KR10: 0 | KS10: 0 | KT10: 5 | KU10: 2148 | KV10: 115 | KW10: 786 | KX10: 12915 | KY10: 598 | KZ10: 1314 | LA10: 7858 | LB10: 188 | LC10: 2694 | LD10: 5057 | LE10: 184 | LF10: 2727 | LG10: 5028 | LH10: 0 | LI10: 0 | LJ10: 0 | LK10: 3 | LL10: 852 | LM10: 29 | LN10: 714 | LO10: 11914 | LP10: 531 | LQ10: 1334 | LR10: 7079 | LS10: 184 | LT10: 2633 | LU10: 4835 | LV10: 175 | LW10: 2719 | LX10: 4763 | LY10: - | LZ10: - | MA10: - | MB10: 8 | MC10: 850 | MD10: 72 | ME10: - | MF10: - | MG10: - | MH10: - | MI10: - | MJ10: - | MK10: - | ML10: - | MM10: 149 | MN10: 2940 | MO10: 4370 | MP10: - | MQ10: - | MR10: - | MS10: - | MT10: - | MU10: - | MV10: - | MW10: - | MX10: - | MY10: - | MZ10: - | NA10: - | NB10: - | NC10: - | ND10: 216 | NE10: 2224 | NF10: 4814 | NG10: - | NH10: - | NI10: - | NJ10: - | NK10: - | NL10: -
A11: 대전광역시 | B11: 소계 | C11: 166 | D11: 3733 | E11: 85 | F11: 1797 | G11: 1527 | H11: 81 | I11: 2723 | J11: 2206 | K11: 80 | L11: 2724 | M11: 2179 | N11: 0 | O11: 0 | P11: 0 | Q11: 1 | R11: 2700 | S11: 27 | T11: 109 | U11: 2343 | V11: 65 | W11: 1787 | X11: 1162 | Y11: 44 | Z11: 2684 | AA11: 1181 | AB11: 44 | AC11: 2685 | AD11: 1181 | AE11: 0 | AF11: 0 | AG11: 0 | AH11: 0 | AI11: 0 | AJ11: 0 | AK11: 155 | AL11: 3284 | AM11: 103 | AN11: 1886 | AO11: 1943 | AP11: 52 | AQ11: 2579 | AR11: 1341 | AS11: 52 | AT11: 2580 | AU11: 1341 | AV11: 0 | AW11: 0 | AX11: 0 | AY11: 0 | AZ11: 0 | BA11: 0 | BB11: 152 | BC11: 3543 | BD11: 93 | BE11: 1878 | BF11: 1747 | BG11: 59 | BH11: 3044 | BI11: 1796 | BJ11: 59 | BK11: 3043 | BL11: 1796 | BM11: 0 | BN11: 0 | BO11: 0 | BP11: 0 | BQ11: 0 | BR11: 0 | BS11: 149 | BT11: 2996 | BU11: 79 | BV11: 1834 | BW11: 1449 | BX11: 70 | BY11: 2210 | BZ11: 1547 | CA11: 70 | CB11: 2210 | CC11: 1547 | CD11: 0 | CE11: 0 | CF11: 0 | CG11: 0 | CH11: 0 | CI11: 0 | CJ11: 149 | CK11: 2497 | CL11: 82 | CM11: 1445 | CN11: 1185 | CO11: 67 | CP11: 1958 | CQ11: 1312 | CR11: 63 | CS11: 1963 | CT11: 1237 | CU11: 0 | CV11: 0 | CW11: 0 | CX11: 4 | CY11: 1864 | CZ11: 75 | DA11: 155 | DB11: 2557 | DC11: 64 | DD11: 1537 | DE11: 984 | DF11: 91 | DG11: 1729 | DH11: 1573 | DI11: 91 | DJ11: 1729 | DK11: 1573 | DL11: 0 | DM11: 0 | DN11: 0 | DO11: 0 | DP11: 0 | DQ11: 0 | DR11: 137 | DS11: 2196 | DT11: 84 | DU11: 1354 | DV11: 1137 | DW11: 53 | DX11: 1998 | DY11: 1059 | DZ11: 53 | EA11: 1998 | EB11: 1059 | EC11: 0 | ED11: 0 | EE11: 0 | EF11: 0 | EG11: 0 | EH11: 0 | EI11: 161 | EJ11: 3104 | EK11: 92 | EL11: 1461 | EM11: 1344 | EN11: 69 | EO11: 2551 | EP11: 1760 | EQ11: 67 | ER11: 2579 | ES11: 1728 | ET11: 0 | EU11: 0 | EV11: 0 | EW11: 2 | EX11: 1619 | EY11: 32 | EZ11: 130 | FA11: 2667 | FB11: 79 | FC11: 1480 | FD11: 1169 | FE11: 51 | FF11: 2937 | FG11: 1498 | FH11: 50 | FI11: 2964 | FJ11: 1482 | FK11: 0 | FL11: 0 | FM11: 0 | FN11: 1 | FO11: 1610 | FP11: 16 | FQ11: 120 | FR11: 2164 | FS11: 68 | FT11: 1514 | FU11: 1030 | FV11: 52 | FW11: 2181 | FX11: 1134 | FY11: 50 | FZ11: 2204 | GA11: 1102 | GB11: 0 | GC11: 0 | GD11: 0 | GE11: 2 | GF11: 1624 | GG11: 32 | GH11: 135 | GI11: 2512 | GJ11: 82 | GK11: 1370 | GL11: 1123 | GM11: 53 | GN11: 2621 | GO11: 1389 | GP11: 50 | GQ11: 2679 | GR11: 1340 | GS11: 0 | GT11: 0 | GU11: 0 | GV11: 3 | GW11: 1629 | GX11: 49 | GY11: 94 | GZ11: 1549 | HA11: 56 | HB11: 1466 | HC11: 818 | HD11: 38 | HE11: 1903 | HF11: 731 | HG11: 36 | HH11: 1884 | HI11: 682 | HJ11: 0 | HK11: 0 | HL11: 0 | HM11: 2 | HN11: 2198 | HO11: 49 | HP11: 87 | HQ11: 1555 | HR11: 44 | HS11: 1435 | HT11: 629 | HU11: 44 | HV11: 2127 | HW11: 926 | HX11: 41 | HY11: 2129 | HZ11: 882 | IA11: 0 | IB11: 0 | IC11: 0 | ID11: 2 | IE11: 2130 | IF11: 44 | IG11: 114 | IH11: 2428 | II11: 62 | IJ11: 1454 | IK11: 902 | IL11: 52 | IM11: 2913 | IN11: 1526 | IO11: 52 | IP11: 2917 | IQ11: 1522 | IR11: 0 | IS11: 0 | IT11: 0 | IU11: 0 | IV11: 1820 | IW11: 4 | IX11: 122 | IY11: 2093 | IZ11: 71 | JA11: 1397 | JB11: 993 | JC11: 51 | JD11: 2157 | JE11: 1100 | JF11: 45 | JG11: 2199 | JH11: 997 | JI11: 0 | JJ11: 0 | JK11: 0 | JL11: 6 | JM11: 1807 | JN11: 103 | JO11: 156 | JP11: 2667 | JQ11: 97 | JR11: 1495 | JS11: 1452 | JT11: 59 | JU11: 2053 | JV11: 1215 | JW11: 49 | JX11: 1985 | JY11: 967 | JZ11: 0 | KA11: 0 | KB11: 0 | KC11: 10 | KD11: 2369 | KE11: 248 | KF11: 122 | KG11: 1971 | KH11: 86 | KI11: 1409 | KJ11: 1216 | KK11: 36 | KL11: 2099 | KM11: 755 | KN11: 34 | KO11: 2081 | KP11: 699 | KQ11: 0 | KR11: 0 | KS11: 0 | KT11: 2 | KU11: 2372 | KV11: 56 | KW11: 133 | KX11: 2409 | KY11: 76 | KZ11: 1407 | LA11: 1068 | LB11: 57 | LC11: 2344 | LD11: 1341 | LE11: 55 | LF11: 2343 | LG11: 1288 | LH11: 0 | LI11: 0 | LJ11: 0 | LK11: 2 | LL11: 2387 | LM11: 53 | LN11: 118 | LO11: 1964 | LP11: 70 | LQ11: 1407 | LR11: 989 | LS11: 48 | LT11: 2037 | LU11: 975 | LV11: 46 | LW11: 2021 | LX11: 925 | LY11: - | LZ11: - | MA11: - | MB11: 2 | MC11: 2387 | MD11: 50 | ME11: - | MF11: - | MG11: - | MH11: - | MI11: - | MJ11: - | MK11: - | ML11: - | MM11: 44 | MN11: 2571 | MO11: 1128 | MP11: - | MQ11: - | MR11: - | MS11: - | MT11: - | MU11: - | MV11: - | MW11: - | MX11: - | MY11: - | MZ11: - | NA11: - | NB11: - | NC11: - | ND11: 29 | NE11: 3047 | NF11: 885 | NG11: - | NH11: - | NI11: - | NJ11: - | NK11: - | NL11: -
A12: 울산광역시 | B12: 소계 | C12: 167 | D12: 3975 | E12: 103 | F12: 1893 | G12: 1950 | H12: 64 | I12: 3164 | J12: 2025 | K12: 59 | L12: 3165 | M12: 1867 | N12: 0 | O12: 0 | P12: 0 | Q12: 5 | R12: 3160 | S12: 158 | T12: 171 | U12: 4560 | V12: 98 | W12: 1835 | X12: 1798 | Y12: 73 | Z12: 3784 | AA12: 2762 | AB12: 69 | AC12: 3828 | AD12: 2641 | AE12: 0 | AF12: 0 | AG12: 0 | AH12: 4 | AI12: 3025 | AJ12: 121 | AK12: 190 | AL12: 4441 | AM12: 115 | AN12: 1934 | AO12: 2224 | AP12: 75 | AQ12: 2956 | AR12: 2217 | AS12: 73 | AT12: 2956 | AU12: 2158 | AV12: 0 | AW12: 0 | AX12: 0 | AY12: 2 | AZ12: 2950 | BA12: 59 | BB12: 174 | BC12: 3773 | BD12: 98 | BE12: 1680 | BF12: 1646 | BG12: 76 | BH12: 2799 | BI12: 2127 | BJ12: 76 | BK12: 2799 | BL12: 2127 | BM12: 0 | BN12: 0 | BO12: 0 | BP12: 0 | BQ12: 0 | BR12: 0 | BS12: 194 | BT12: 4136 | BU12: 114 | BV12: 1692 | BW12: 1929 | BX12: 80 | BY12: 2759 | BZ12: 2207 | CA12: 78 | CB12: 2767 | CC12: 2158 | CD12: 0 | CE12: 0 | CF12: 0 | CG12: 2 | CH12: 2425 | CI12: 49 | CJ12: 153 | CK12: 2815 | CL12: 83 | CM12: 1690 | CN12: 1403 | CO12: 70 | CP12: 2017 | CQ12: 1412 | CR12: 66 | CS12: 2005 | CT12: 1323 | CU12: 0 | CV12: 0 | CW12: 0 | CX12: 4 | CY12: 2215 | CZ12: 89 | DA12: 202 | DB12: 4427 | DC12: 100 | DD12: 1664 | DE12: 1664 | DF12: 102 | DG12: 2709 | DH12: 2763 | DI12: 101 | DJ12: 2714 | DK12: 2741 | DL12: 0 | DM12: 0 | DN12: 0 | DO12: 1 | DP12: 2200 | DQ12: 22 | DR12: 182 | DS12: 4226 | DT12: 90 | DU12: 1649 | DV12: 1484 | DW12: 92 | DX12: 2980 | DY12: 2742 | DZ12: 92 | EA12: 2981 | EB12: 2742 | EC12: 0 | ED12: 0 | EE12: 0 | EF12: 0 | EG12: 0 | EH12: 0 | EI12: 230 | EJ12: 4848 | EK12: 115 | EL12: 1539 | EM12: 1770 | EN12: 115 | EO12: 2677 | EP12: 3078 | EQ12: 108 | ER12: 2716 | ES12: 2933 | ET12: 0 | EU12: 0 | EV12: 0 | EW12: 7 | EX12: 2077 | EY12: 145 | EZ12: 200 | FA12: 4528 | FB12: 108 | FC12: 1567 | FD12: 1692 | FE12: 92 | FF12: 3083 | FG12: 2836 | FH12: 92 | FI12: 3082 | FJ12: 2836 | FK12: 0 | FL12: 0 | FM12: 0 | FN12: 0 | FO12: 0 | FP12: 0 | FQ12: 152 | FR12: 3110 | FS12: 95 | FT12: 1543 | FU12: 1466 | FV12: 57 | FW12: 2884 | FX12: 1644 | FY12: 57 | FZ12: 2885 | GA12: 1644 | GB12: 0 | GC12: 0 | GD12: 0 | GE12: 0 | GF12: 0 | GG12: 0 | GH12: 159 | GI12: 3103 | GJ12: 94 | GK12: 1505 | GL12: 1415 | GM12: 65 | GN12: 2597 | GO12: 1688 | GP12: 64 | GQ12: 2605 | GR12: 1667 | GS12: 0 | GT12: 0 | GU12: 0 | GV12: 1 | GW12: 2053 | GX12: 21 | GY12: 177 | GZ12: 3515 | HA12: 111 | HB12: 1828 | HC12: 2025 | HD12: 66 | HE12: 2261 | HF12: 1490 | HG12: 63 | HH12: 2296 | HI12: 1449 | HJ12: 0 | HK12: 0 | HL12: 0 | HM12: 3 | HN12: 1445 | HO12: 41 | HP12: 216 | HQ12: 3163 | HR12: 119 | HS12: 563 | HT12: 670 | HU12: 97 | HV12: 2580 | HW12: 2493 | HX12: 94 | HY12: 2617 | HZ12: 2472 | IA12: 0 | IB12: 0 | IC12: 0 | ID12: 2 | IE12: 975 | IF12: 21 | IG12: 227 | IH12: 3010 | II12: 107 | IJ12: 563 | IK12: 604 | IL12: 119 | IM12: 2019 | IN12: 2406 | IO12: 118 | IP12: 2027 | IQ12: 2397 | IR12: 0 | IS12: 0 | IT12: 0 | IU12: 1 | IV12: 952 | IW12: 9 | IX12: 197 | IY12: 2108 | IZ12: 129 | JA12: 565 | JB12: 728 | JC12: 69 | JD12: 2012 | JE12: 1380 | JF12: 67 | JG12: 2033 | JH12: 1368 | JI12: 0 | JJ12: 0 | JK12: 0 | JL12: 1 | JM12: 951 | JN12: 12 | JO12: 241 | JP12: 3682 | JQ12: 156 | JR12: 975 | JS12: 1522 | JT12: 85 | JU12: 2538 | JV12: 2160 | JW12: 69 | JX12: 2881 | JY12: 2002 | JZ12: 0 | KA12: 0 | KB12: 0 | KC12: 16 | KD12: 1010 | KE12: 158 | KF12: 250 | KG12: 3475 | KH12: 149 | KI12: 919 | KJ12: 1365 | KK12: 102 | KL12: 2073 | KM12: 2110 | KN12: 88 | KO12: 2242 | KP12: 1962 | KQ12: 0 | KR12: 0 | KS12: 0 | KT12: 14 | KU12: 1036 | KV12: 148 | KW12: 206 | KX12: 2564 | KY12: 130 | KZ12: 536 | LA12: 696 | LB12: 77 | LC12: 2442 | LD12: 1868 | LE12: 73 | LF12: 2509 | LG12: 1838 | LH12: 0 | LI12: 0 | LJ12: 0 | LK12: 3 | LL12: 924 | LM12: 30 | LN12: 185 | LO12: 2744 | LP12: 102 | LQ12: 590 | LR12: 603 | LS12: 83 | LT12: 2579 | LU12: 2141 | LV12: 77 | LW12: 2720 | LX12: 2091 | LY12: - | LZ12: - | MA12: - | MB12: 6 | MC12: 822 | MD12: 50 | ME12: - | MF12: - | MG12: - | MH12: - | MI12: - | MJ12: - | MK12: - | ML12: - | MM12: 95 | MN12: 2972 | MO12: 2835 | MP12: - | MQ12: - | MR12: - | MS12: - | MT12: - | MU12: - | MV12: - | MW12: - | MX12: - | MY12: - | MZ12: - | NA12: - | NB12: - | NC12: - | ND12: 87 | NE12: 2354 | NF12: 2058 | NG12: - | NH12: - | NI12: - | NJ12: - | NK12: - | NL12: -
A13: 세종특별자치시 | B13: 소계 | C13: - | D13: - | E13: - | F13: - | G13: - | H13: - | I13: - | J13: - | K13: - | L13: - | M13: - | N13: - | O13: - | P13: - | Q13: - | R13: - | S13: - | T13: - | U13: - | V13: - | W13: - | X13: - | Y13: - | Z13: - | AA13: - | AB13: - | AC13: - | AD13: - | AE13: - | AF13: - | AG13: - | AH13: - | AI13: - | AJ13: - | AK13: - | AL13: - | AM13: - | AN13: - | AO13: - | AP13: - | AQ13: - | AR13: - | AS13: - | AT13: - | AU13: - | AV13: - | AW13: - | AX13: - | AY13: - | AZ13: - | BA13: - | BB13: - | BC13: - | BD13: - | BE13: - | BF13: - | BG13: - | BH13: - | BI13: - | BJ13: - | BK13: - | BL13: - | BM13: - | BN13: - | BO13: - | BP13: - | BQ13: - | BR13: - | BS13: - | BT13: - | BU13: - | BV13: - | BW13: - | BX13: - | BY13: - | BZ13: - | CA13: - | CB13: - | CC13: - | CD13: - | CE13: - | CF13: - | CG13: - | CH13: - | CI13: - | CJ13: - | CK13: - | CL13: - | CM13: - | CN13: - | CO13: - | CP13: - | CQ13: - | CR13: - | CS13: - | CT13: - | CU13: - | CV13: - | CW13: - | CX13: - | CY13: - | CZ13: - | DA13: - | DB13: - | DC13: - | DD13: - | DE13: - | DF13: - | DG13: - | DH13: - | DI13: - | DJ13: - | DK13: - | DL13: - | DM13: - | DN13: - | DO13: - | DP13: - | DQ13: - | DR13: - | DS13: - | DT13: - | DU13: - | DV13: - | DW13: - | DX13: - | DY13: - | DZ13: - | EA13: - | EB13: - | EC13: - | ED13: - | EE13: - | EF13: - | EG13: - | EH13: - | EI13: - | EJ13: - | EK13: - | EL13: - | EM13: - | EN13: - | EO13: - | EP13: - | EQ13: - | ER13: - | ES13: - | ET13: - | EU13: - | EV13: - | EW13: - | EX13: - | EY13: - | EZ13: - | FA13: - | FB13: - | FC13: - | FD13: - | FE13: - | FF13: - | FG13: - | FH13: - | FI13: - | FJ13: - | FK13: - | FL13: - | FM13: - | FN13: - | FO13: - | FP13: - | FQ13: - | FR13: - | FS13: - | FT13: - | FU13: - | FV13: - | FW13: - | FX13: - | FY13: - | FZ13: - | GA13: - | GB13: - | GC13: - | GD13: - | GE13: - | GF13: - | GG13: - | GH13: 157 | GI13: 2618 | GJ13: 106 | GK13: 1331 | GL13: 1411 | GM13: 51 | GN13: 2367 | GO13: 1207 | GP13: 51 | GQ13: 2366 | GR13: 1207 | GS13: 0 | GT13: 0 | GU13: 0 | GV13: 0 | GW13: 0 | GX13: 0 | GY13: 145 | GZ13: 2120 | HA13: 89 | HB13: 1163 | HC13: 1039 | HD13: 55 | HE13: 1950 | HF13: 1081 | HG13: 47 | HH13: 2128 | HI13: 993 | HJ13: 0 | HK13: 0 | HL13: 0 | HM13: 9 | HN13: 1000 | HO13: 88 | HP13: 101 | HQ13: 1582 | HR13: 70 | HS13: 1146 | HT13: 797 | HU13: 32 | HV13: 2485 | HW13: 785 | HX13: 31 | HY13: 2506 | HZ13: 781 | IA13: 0 | IB13: 0 | IC13: 0 | ID13: 0 | IE13: 1052 | IF13: 4 | IG13: 112 | IH13: 1679 | II13: 61 | IJ13: 945 | IK13: 580 | IL13: 50 | IM13: 2183 | IN13: 1099 | IO13: 49 | IP13: 2208 | IQ13: 1091 | IR13: 0 | IS13: 0 | IT13: 0 | IU13: 1 | IV13: 887 | IW13: 8 | IX13: 136 | IY13: 1804 | IZ13: 63 | JA13: 984 | JB13: 617 | JC13: 73 | JD13: 1617 | JE13: 1187 | JF13: 47 | JG13: 1759 | JH13: 821 | JI13: 0 | JJ13: 0 | JK13: 0 | JL13: 27 | JM13: 1370 | JN13: 366 | JO13: 129 | JP13: 1596 | JQ13: 77 | JR13: 561 | JS13: 432 | JT13: 52 | JU13: 2220 | JV13: 1164 | JW13: 52 | JX13: 2220 | JY13: 1164 | JZ13: 0 | KA13: 0 | KB13: 0 | KC13: 0 | KD13: 0 | KE13: 0 | KF13: 106 | KG13: 1159 | KH13: 66 | KI13: 575 | KJ13: 377 | KK13: 40 | KL13: 1940 | KM13: 782 | KN13: 39 | KO13: 1962 | KP13: 774 | KQ13: 0 | KR13: 0 | KS13: 0 | KT13: 1 | KU13: 958 | KV13: 8 | KW13: 92 | KX13: 1127 | KY13: 56 | KZ13: 902 | LA13: 508 | LB13: 36 | LC13: 1743 | LD13: 619 | LE13: 35 | LF13: 1744 | LG13: 619 | LH13: 0 | LI13: 0 | LJ13: 0 | LK13: 0 | LL13: 1017 | LM13: 0 | LN13: 82 | LO13: 1446 | LP13: 52 | LQ13: 1429 | LR13: 740 | LS13: 30 | LT13: 2325 | LU13: 706 | LV13: 30 | LW13: 2340 | LX13: 697 | LY13: - | LZ13: - | MA13: - | MB13: 1 | MC13: 1593 | MD13: 9 | ME13: - | MF13: - | MG13: - | MH13: - | MI13: - | MJ13: - | MK13: - | ML13: - | MM13: 67 | MN13: 3114 | MO13: 2080 | MP13: - | MQ13: - | MR13: - | MS13: - | MT13: - | MU13: - | MV13: - | MW13: - | MX13: - | MY13: - | MZ13: - | NA13: - | NB13: - | NC13: - | ND13: 44 | NE13: 1877 | NF13: 834 | NG13: - | NH13: - | NI13: - | NJ13: - | NK13: - | NL13: -
